Workbook

Sheet งบกำไรขาดทุน ปี 2025
B1: THONGLOR PET HOSPITAL COMPANY LIMITED
B2: บริษัท โรงพยาบาลสัตว์ทองหล่อ จำกัด
C4: Act ปี 2025 | Q4: %ต่อยอดขาย Act ปี 2025
C5: January | D5: February | E5: March | F5: April | G5: May | H5: June | I5: July | J5: August | K5: September | L5: October | M5: November | N5: December | O5: YTD | Q5: January | R5: February | S5: March | T5: April | U5: May | V5: June | W5: July | X5: August | Y5: September | Z5: October | AA5: November | AB5: December | AC5: YTD
B6: รายได้
B7: รายได้จากการขายและอื่นๆ
A8: 41100001 | B8: รายได้จากการขาย - OPD/IPD | O8: =SUM(C8:N8) -> 0 | Q8: =C8/C$18 -> #DIV/0! | R8: =D8/D$18 -> #DIV/0! | S8: =E8/E$18 -> #DIV/0! | T8: =F8/F$18 -> #DIV/0! | U8: =G8/G$18 -> #DIV/0! | V8: =H8/H$18 -> #DIV/0! | W8: =I8/I$18 -> #DIV/0! | X8: =J8/J$18 -> #DIV/0! | ... AC8: =O8/O$18 -> #DIV/0!
A9: 41200001 | B9: รายได้จากการขาย - Grooming | O9: =SUM(C9:N9) -> 0 | Q9: =C9/C$18 -> #DIV/0! | R9: =D9/D$18 -> #DIV/0! | S9: =E9/E$18 -> #DIV/0! | T9: =F9/F$18 -> #DIV/0! | U9: =G9/G$18 -> #DIV/0! | V9: =H9/H$18 -> #DIV/0! | W9: =I9/I$18 -> #DIV/0! | X9: =J9/J$18 -> #DIV/0! | ... AC9: =O9/O$18 -> #DIV/0!
A10: 41100002 | B10: รายได้จากการขาย - Petshop | O10: =SUM(C10:N10) -> 0 | Q10: =C10/C$18 -> #DIV/0! | R10: =D10/D$18 -> #DIV/0! | S10: =E10/E$18 -> #DIV/0! | T10: =F10/F$18 -> #DIV/0! | U10: =G10/G$18 -> #DIV/0! | V10: =H10/H$18 -> #DIV/0! | W10: =I10/I$18 -> #DIV/0! | X10: =J10/J$18 -> #DIV/0! | ... AC10: =O10/O$18 -> #DIV/0!
A11: 41200004 | B11: รายได้จากการขาย - Swimming | O11: =SUM(C11:N11) -> 0 | Q11: =C11/C$18 -> #DIV/0! | R11: =D11/D$18 -> #DIV/0! | S11: =E11/E$18 -> #DIV/0! | T11: =F11/F$18 -> #DIV/0! | U11: =G11/G$18 -> #DIV/0! | V11: =H11/H$18 -> #DIV/0! | W11: =I11/I$18 -> #DIV/0! | X11: =J11/J$18 -> #DIV/0! | ... AC11: =O11/O$18 -> #DIV/0!
A12: 41200002 | B12: รายได้จากการขาย - Pettaxi | O12: =SUM(C12:N12) -> 0 | Q12: =C12/C$18 -> #DIV/0! | R12: =D12/D$18 -> #DIV/0! | S12: =E12/E$18 -> #DIV/0! | T12: =F12/F$18 -> #DIV/0! | U12: =G12/G$18 -> #DIV/0! | V12: =H12/H$18 -> #DIV/0! | W12: =I12/I$18 -> #DIV/0! | X12: =J12/J$18 -> #DIV/0! | ... AC12: =O12/O$18 -> #DIV/0!
A13: 41200003 | B13: รายได้จากการขาย - อื่นๆ | O13: =SUM(C13:N13) -> 0 | Q13: =C13/C$18 -> #DIV/0! | R13: =D13/D$18 -> #DIV/0! | S13: =E13/E$18 -> #DIV/0! | T13: =F13/F$18 -> #DIV/0! | U13: =G13/G$18 -> #DIV/0! | V13: =H13/H$18 -> #DIV/0! | W13: =I13/I$18 -> #DIV/0! | X13: =J13/J$18 -> #DIV/0! | ... AC13: =O13/O$18 -> #DIV/0!
A14: 41300001 | B14: หัก รับคืน | O14: =SUM(C14:N14) -> 0 | Q14: =C14/C$18 -> #DIV/0! | R14: =D14/D$18 -> #DIV/0! | S14: =E14/E$18 -> #DIV/0! | T14: =F14/F$18 -> #DIV/0! | U14: =G14/G$18 -> #DIV/0! | V14: =H14/H$18 -> #DIV/0! | W14: =I14/I$18 -> #DIV/0! | X14: =J14/J$18 -> #DIV/0! | ... AC14: =O14/O$18 -> #DIV/0!
A15: 41300002 | B15: หัก ส่วนลดจ่าย | O15: =SUM(C15:N15) -> 0 | Q15: =C15/C$18 -> #DIV/0! | R15: =D15/D$18 -> #DIV/0! | S15: =E15/E$18 -> #DIV/0! | T15: =F15/F$18 -> #DIV/0! | U15: =G15/G$18 -> #DIV/0! | V15: =H15/H$18 -> #DIV/0! | W15: =I15/I$18 -> #DIV/0! | X15: =J15/J$18 -> #DIV/0! | ... AC15: =O15/O$18 -> #DIV/0!
A16: 42000001 | B16: รายได้อื่นๆ | O16: =SUM(C16:N16) -> 0 | Q16: =C16/C$18 -> #DIV/0! | R16: =D16/D$18 -> #DIV/0! | S16: =E16/E$18 -> #DIV/0! | T16: =F16/F$18 -> #DIV/0! | U16: =G16/G$18 -> #DIV/0! | V16: =H16/H$18 -> #DIV/0! | W16: =I16/I$18 -> #DIV/0! | X16: =J16/J$18 -> #DIV/0! | ... AC16: =O16/O$18 -> #DIV/0!
A17: 42000019 | B17: รายได้ Package/PR/ขนส่ง
B18: รวมรายได้จาการขายและอื่นๆ | O18: =SUM(C18:N18) -> 0 | Q18: =C18/C$18 -> #DIV/0! | R18: =D18/D$18 -> #DIV/0! | S18: =E18/E$18 -> #DIV/0! | T18: =F18/F$18 -> #DIV/0! | U18: =G18/G$18 -> #DIV/0! | V18: =H18/H$18 -> #DIV/0! | W18: =I18/I$18 -> #DIV/0! | X18: =J18/J$18 -> #DIV/0! | ... AC18: =O18/O$18 -> #DIV/0!
B19: ต้นทุนขายและค่าใช้จ่ายที่เกี่ยวข้อง | O19: =SUM(C19:N19) -> 0
B20: ต้นทุนขาย | O20: =SUM(C20:N20) -> 0
A21: 51000002 | B21: ต้นทุนขายสินค้า PH | O21: =SUM(C21:N21) -> 0 | Q21: =C21/C$18 -> #DIV/0! | R21: =D21/D$18 -> #DIV/0! | S21: =E21/E$18 -> #DIV/0! | T21: =F21/F$18 -> #DIV/0! | U21: =G21/G$18 -> #DIV/0! | V21: =H21/H$18 -> #DIV/0! | W21: =I21/I$18 -> #DIV/0! | X21: =J21/J$18 -> #DIV/0! | ... AC21: =O21/O$18 -> #DIV/0!
A22: 51000003 | B22: ต้นทุนขายสินค้า PC | O22: =SUM(C22:N22) -> 0 | Q22: =C22/C$18 -> #DIV/0! | R22: =D22/D$18 -> #DIV/0! | S22: =E22/E$18 -> #DIV/0! | T22: =F22/F$18 -> #DIV/0! | U22: =G22/G$18 -> #DIV/0! | V22: =H22/H$18 -> #DIV/0! | W22: =I22/I$18 -> #DIV/0! | X22: =J22/J$18 -> #DIV/0! | ... AC22: =O22/O$18 -> #DIV/0!
A23: 51000004 | B23: หัก ส่วนลดรับ | O23: =SUM(C23:N23) -> 0 | Q23: =C23/C$18 -> #DIV/0! | R23: =D23/D$18 -> #DIV/0! | S23: =E23/E$18 -> #DIV/0! | T23: =F23/F$18 -> #DIV/0! | U23: =G23/G$18 -> #DIV/0! | V23: =H23/H$18 -> #DIV/0! | W23: =I23/I$18 -> #DIV/0! | X23: =J23/J$18 -> #DIV/0! | ... AC23: =O23/O$18 -> #DIV/0!
A24: 51000001 | B24: รวมต้นทุนขาย | O24: =SUM(C24:N24) -> 0 | Q24: =C24/C$18 -> #DIV/0! | R24: =D24/D$18 -> #DIV/0! | S24: =E24/E$18 -> #DIV/0! | T24: =F24/F$18 -> #DIV/0! | U24: =G24/G$18 -> #DIV/0! | V24: =H24/H$18 -> #DIV/0! | W24: =I24/I$18 -> #DIV/0! | X24: =J24/J$18 -> #DIV/0! | ... AC24: =O24/O$18 -> #DIV/0!
B25: ค่าใช้จ่ายในการขาย | O25: =SUM(C25:N25) -> 0
A26: 52000017 | B26: ค่าใช้จ่ายในการขาย และค่าธรรมเนียม | O26: =SUM(C26:N26) -> 0 | Q26: =C26/C$18 -> #DIV/0! | R26: =D26/D$18 -> #DIV/0! | S26: =E26/E$18 -> #DIV/0! | T26: =F26/F$18 -> #DIV/0! | U26: =G26/G$18 -> #DIV/0! | V26: =H26/H$18 -> #DIV/0! | W26: =I26/I$18 -> #DIV/0! | X26: =J26/J$18 -> #DIV/0! | ... AC26: =O26/O$18 -> #DIV/0!
A27: 52000001 | B27: ค่าส่งเสริมการขาย | O27: =SUM(C27:N27) -> 0 | Q27: =C27/C$18 -> #DIV/0! | R27: =D27/D$18 -> #DIV/0! | S27: =E27/E$18 -> #DIV/0! | T27: =F27/F$18 -> #DIV/0! | U27: =G27/G$18 -> #DIV/0! | V27: =H27/H$18 -> #DIV/0! | W27: =I27/I$18 -> #DIV/0! | X27: =J27/J$18 -> #DIV/0! | ... AC27: =O27/O$18 -> #DIV/0!
A28: 52000003 | B28: ค่าชันสูตรโรค | O28: =SUM(C28:N28) -> 0 | Q28: =C28/C$18 -> #DIV/0! | R28: =D28/D$18 -> #DIV/0! | S28: =E28/E$18 -> #DIV/0! | T28: =F28/F$18 -> #DIV/0! | U28: =G28/G$18 -> #DIV/0! | V28: =H28/H$18 -> #DIV/0! | W28: =I28/I$18 -> #DIV/0! | X28: =J28/J$18 -> #DIV/0! | ... AC28: =O28/O$18 -> #DIV/0!
A29: 52000004 | B29: ค่าส่งเผา | O29: =SUM(C29:N29) -> 0 | Q29: =C29/C$18 -> #DIV/0! | R29: =D29/D$18 -> #DIV/0! | S29: =E29/E$18 -> #DIV/0! | T29: =F29/F$18 -> #DIV/0! | U29: =G29/G$18 -> #DIV/0! | V29: =H29/H$18 -> #DIV/0! | W29: =I29/I$18 -> #DIV/0! | X29: =J29/J$18 -> #DIV/0! | ... AC29: =O29/O$18 -> #DIV/0!
A30: 52000005 | B30: ค่าตรวจเลือด | O30: =SUM(C30:N30) -> 0 | Q30: =C30/C$18 -> #DIV/0! | R30: =D30/D$18 -> #DIV/0! | S30: =E30/E$18 -> #DIV/0! | T30: =F30/F$18 -> #DIV/0! | U30: =G30/G$18 -> #DIV/0! | V30: =H30/H$18 -> #DIV/0! | W30: =I30/I$18 -> #DIV/0! | X30: =J30/J$18 -> #DIV/0! | ... AC30: =O30/O$18 -> #DIV/0!
A31: 52000006 | B31: ค่าตรวจเลือดภายใน | O31: =SUM(C31:N31) -> 0 | Q31: =C31/C$18 -> #DIV/0! | R31: =D31/D$18 -> #DIV/0! | S31: =E31/E$18 -> #DIV/0! | T31: =F31/F$18 -> #DIV/0! | U31: =G31/G$18 -> #DIV/0! | V31: =H31/H$18 -> #DIV/0! | W31: =I31/I$18 -> #DIV/0! | X31: =J31/J$18 -> #DIV/0! | ... AC31: =O31/O$18 -> #DIV/0!
A32: 52000007 | B32: ค่าเช่าเครื่องมือภายใน | O32: =SUM(C32:N32) -> 0 | Q32: =C32/C$18 -> #DIV/0! | R32: =D32/D$18 -> #DIV/0! | S32: =E32/E$18 -> #DIV/0! | T32: =F32/F$18 -> #DIV/0! | U32: =G32/G$18 -> #DIV/0! | V32: =H32/H$18 -> #DIV/0! | W32: =I32/I$18 -> #DIV/0! | X32: =J32/J$18 -> #DIV/0! | ... AC32: =O32/O$18 -> #DIV/0!
A33: 52000008 | B33: ค่าบริการวิชาชีพแพทย์ | O33: =SUM(C33:N33) -> 0 | Q33: =C33/C$18 -> #DIV/0! | R33: =D33/D$18 -> #DIV/0! | S33: =E33/E$18 -> #DIV/0! | T33: =F33/F$18 -> #DIV/0! | U33: =G33/G$18 -> #DIV/0! | V33: =H33/H$18 -> #DIV/0! | W33: =I33/I$18 -> #DIV/0! | X33: =J33/J$18 -> #DIV/0! | ... AC33: =O33/O$18 -> #DIV/0!
A34: 52000010 | B34: ค่าเช่าเครื่องมือแพทย์ | O34: =SUM(C34:N34) -> 0 | Q34: =C34/C$18 -> #DIV/0! | R34: =D34/D$18 -> #DIV/0! | S34: =E34/E$18 -> #DIV/0! | T34: =F34/F$18 -> #DIV/0! | U34: =G34/G$18 -> #DIV/0! | V34: =H34/H$18 -> #DIV/0! | W34: =I34/I$18 -> #DIV/0! | X34: =J34/J$18 -> #DIV/0! | ... AC34: =O34/O$18 -> #DIV/0!
A35: 52000011 | B35: ค่าวัสดุเครื่องมือแพทย์ | O35: =SUM(C35:N35) -> 0 | Q35: =C35/C$18 -> #DIV/0! | R35: =D35/D$18 -> #DIV/0! | S35: =E35/E$18 -> #DIV/0! | T35: =F35/F$18 -> #DIV/0! | U35: =G35/G$18 -> #DIV/0! | V35: =H35/H$18 -> #DIV/0! | W35: =I35/I$18 -> #DIV/0! | X35: =J35/J$18 -> #DIV/0! | ... AC35: =O35/O$18 -> #DIV/0!
A36: 52000014 | B36: ค่าเช่าอุปกรณ์-เครื่องมือระหว่างสาขา | O36: =SUM(C36:N36) -> 0 | Q36: =C36/C$18 -> #DIV/0! | R36: =D36/D$18 -> #DIV/0! | S36: =E36/E$18 -> #DIV/0! | T36: =F36/F$18 -> #DIV/0! | U36: =G36/G$18 -> #DIV/0! | V36: =H36/H$18 -> #DIV/0! | W36: =I36/I$18 -> #DIV/0! | X36: =J36/J$18 -> #DIV/0! | ... AC36: =O36/O$18 -> #DIV/0!
A37: 61300010 | B37: ค่าเสื่อมราคา - เครื่องมือแพทย์ | O37: =SUM(C37:N37) -> 0 | Q37: =C37/C$18 -> #DIV/0! | R37: =D37/D$18 -> #DIV/0! | S37: =E37/E$18 -> #DIV/0! | T37: =F37/F$18 -> #DIV/0! | U37: =G37/G$18 -> #DIV/0! | V37: =H37/H$18 -> #DIV/0! | W37: =I37/I$18 -> #DIV/0! | X37: =J37/J$18 -> #DIV/0! | ... AC37: =O37/O$18 -> #DIV/0!
B38: รวมค่าใช้จ่ายในการขาย | O38: =SUM(C38:N38) -> 0 | Q38: =C38/C$18 -> #DIV/0! | R38: =D38/D$18 -> #DIV/0! | S38: =E38/E$18 -> #DIV/0! | T38: =F38/F$18 -> #DIV/0! | U38: =G38/G$18 -> #DIV/0! | V38: =H38/H$18 -> #DIV/0! | W38: =I38/I$18 -> #DIV/0! | X38: =J38/J$18 -> #DIV/0! | ... AC38: =O38/O$18 -> #DIV/0!
B39: ค่ายานพาหนะ | O39: =SUM(C39:N39) -> 0
A40: 52000015 | B40: ค่าขนส่งในประเทศ | O40: =SUM(C40:N40) -> 0 | Q40: =C40/C$18 -> #DIV/0! | R40: =D40/D$18 -> #DIV/0! | S40: =E40/E$18 -> #DIV/0! | T40: =F40/F$18 -> #DIV/0! | U40: =G40/G$18 -> #DIV/0! | V40: =H40/H$18 -> #DIV/0! | W40: =I40/I$18 -> #DIV/0! | X40: =J40/J$18 -> #DIV/0! | ... AC40: =O40/O$18 -> #DIV/0!
B41: รวมค่ายานพาหนะ | O41: =SUM(C41:N41) -> 0 | Q41: =C41/C$18 -> #DIV/0! | R41: =D41/D$18 -> #DIV/0! | S41: =E41/E$18 -> #DIV/0! | T41: =F41/F$18 -> #DIV/0! | U41: =G41/G$18 -> #DIV/0! | V41: =H41/H$18 -> #DIV/0! | W41: =I41/I$18 -> #DIV/0! | X41: =J41/J$18 -> #DIV/0! | ... AC41: =O41/O$18 -> #DIV/0!
...

Sheet Budget ปี 2026
B1: THONGLOR PET HOSPITAL COMPANY LIMITED | G1: F | H1: Fixed
B2: บริษัท โรงพยาบาลสัตว์ทองหล่อ จำกัด | G2: V | H2: Variable | S2: 0.5 | T2: % การโต2 | U2: =S2*U3 -> #DIV/0! | V2: >for fixed expense
G3: z | H3: Zero-based: คำนวนใหม่ตามใช้จริง | T3: % การโต | U3: =(U18-E18)/E18 -> #DIV/0! | V3: >revenue%
C4: Act จริง | F4: สัดส่วน/ยอดขาย | G4: % การโต | I4: BG ปี 2025 ( ครึ่งปี แรก) | O4: BG ปี 2025 (ครึ่งปี หลัง) | U4: TOTAL | V4: ส้ดส่วน/ยอดขาย
C5: 9 | D5: ต่อเดือน | E5: 12 | H5: R,F,V,Z | I5: January | J5: February | K5: March | L5: April | M5: May | N5: June | O5: July | P5: August | Q5: September | R5: October | S5: November | T5: December | V5: January | W5: February | X5: March | Y5: April | Z5: May | AA5: June | AB5: July | AC5: August | AD5: September | AE5: October | AF5: November | AG5: December | AH5: TOTAL
A6: ='งบกำไรขาดทุน ปี 2025'!A6 -> 0 | B6: ='งบกำไรขาดทุน ปี 2025'!B6 -> รายได้ | AJ6: =IFERROR(U6/E6,0)-1 -> -1
A7: ='งบกำไรขาดทุน ปี 2025'!A7 -> 0 | B7: ='งบกำไรขาดทุน ปี 2025'!B7 -> รายได้จากการขายและอื่นๆ | AJ7: =IFERROR(U7/E7,0)-1 -> -1
A8: ='งบกำไรขาดทุน ปี 2025'!A8 -> 41100001 | B8: ='งบกำไรขาดทุน ปี 2025'!B8 -> รายได้จากการขาย - OPD/IPD | C8: ='งบกำไรขาดทุน ปี 2025'!O8 -> 0 | D8: =C8/$C$5 -> 0 | E8: =D8*$E$5 -> 0 | F8: =E8/$E$18 -> #DIV/0! | H8: R | I8: ='การลงระหว่างเดือน ปี 2026'!E7 -> 0 | J8: ='การลงระหว่างเดือน ปี 2026'!H7 -> 0 | K8: ='การลงระหว่างเดือน ปี 2026'!K7 -> 0 | L8: ='การลงระหว่างเดือน ปี 2026'!N7 -> 0 | M8: ='การลงระหว่างเดือน ปี 2026'!Q7 -> 0 | N8: ='การลงระหว่างเดือน ปี 2026'!T7 -> 0 | O8: ='การลงระหว่างเดือน ปี 2026'!W7 -> 0 | P8: ='การลงระหว่างเดือน ปี 2026'!Z7 -> 0 | Q8: ='การลงระหว่างเดือน ปี 2026'!AC7 -> 0 | R8: ='การลงระหว่างเดือน ปี 2026'!AF7 -> 0 | S8: ='การลงระหว่างเดือน ปี 2026'!AI7 -> 0 | T8: ='การลงระหว่างเดือน ปี 2026'!AL7 -> 0 | U8: =SUM(I8:T8) -> 0 | V8: =I8/$I$18 -> #DIV/0! | W8: =J8/$J$18 -> #DIV/0! | X8: =K8/$K$18 -> #DIV/0! | Y8: =L8/$L$18 -> #DIV/0! | Z8: =M8/$M$18 -> #DIV/0! | AA8: =N8/$N$18 -> #DIV/0! | AB8: =O8/$O$18 -> #DIV/0! | AC8: =P8/$P$18 -> #DIV/0! | AD8: =Q8/$Q$18 -> #DIV/0! | AE8: =R8/$R$18 -> #DIV/0! | AF8: =S8/$S$18 -> #DIV/0! | AG8: =T8/$T$18 -> #DIV/0! | AH8: =U8/$U$18 -> #DIV/0! | AI8: R | AJ8: =IFERROR(U8/E8,0)-1 -> -1
A9: ='งบกำไรขาดทุน ปี 2025'!A9 -> 41200001 | B9: ='งบกำไรขาดทุน ปี 2025'!B9 -> รายได้จากการขาย - Grooming | C9: ='งบกำไรขาดทุน ปี 2025'!O9 -> 0 | D9: =C9/$C$5 -> 0 | E9: =D9*$E$5 -> 0 | F9: =E9/$E$18 -> #DIV/0! | H9: R | I9: ='การลงระหว่างเดือน ปี 2026'!E8 -> 0 | J9: ='การลงระหว่างเดือน ปี 2026'!H8 -> 0 | K9: ='การลงระหว่างเดือน ปี 2026'!K8 -> 0 | L9: ='การลงระหว่างเดือน ปี 2026'!N8 -> 0 | M9: ='การลงระหว่างเดือน ปี 2026'!Q8 -> 0 | N9: ='การลงระหว่างเดือน ปี 2026'!T8 -> 0 | O9: ='การลงระหว่างเดือน ปี 2026'!W8 -> 0 | P9: ='การลงระหว่างเดือน ปี 2026'!Z8 -> 0 | Q9: ='การลงระหว่างเดือน ปี 2026'!AC8 -> 0 | R9: ='การลงระหว่างเดือน ปี 2026'!AF8 -> 0 | S9: ='การลงระหว่างเดือน ปี 2026'!AI8 -> 0 | T9: ='การลงระหว่างเดือน ปี 2026'!AL8 -> 0 | U9: =SUM(I9:T9) -> 0 | V9: =I9/$I$18 -> #DIV/0! | W9: =J9/$J$18 -> #DIV/0! | X9: =K9/$K$18 -> #DIV/0! | Y9: =L9/$L$18 -> #DIV/0! | Z9: =M9/$M$18 -> #DIV/0! | AA9: =N9/$N$18 -> #DIV/0! | AB9: =O9/$O$18 -> #DIV/0! | AC9: =P9/$P$18 -> #DIV/0! | AD9: =Q9/$Q$18 -> #DIV/0! | AE9: =R9/$R$18 -> #DIV/0! | AF9: =S9/$S$18 -> #DIV/0! | AG9: =T9/$T$18 -> #DIV/0! | AH9: =U9/$U$18 -> #DIV/0! | AI9: R | AJ9: =IFERROR(U9/E9,0)-1 -> -1
A10: ='งบกำไรขาดทุน ปี 2025'!A10 -> 41100002 | B10: ='งบกำไรขาดทุน ปี 2025'!B10 -> รายได้จากการขาย - Petshop | C10: ='งบกำไรขาดทุน ปี 2025'!O10 -> 0 | D10: =C10/$C$5 -> 0 | E10: =D10*$E$5 -> 0 | F10: =E10/$E$18 -> #DIV/0! | H10: R | I10: ='การลงระหว่างเดือน ปี 2026'!E9 -> 0 | J10: ='การลงระหว่างเดือน ปี 2026'!H9 -> 0 | K10: ='การลงระหว่างเดือน ปี 2026'!K9 -> 0 | L10: ='การลงระหว่างเดือน ปี 2026'!N9 -> 0 | M10: ='การลงระหว่างเดือน ปี 2026'!Q9 -> 0 | N10: ='การลงระหว่างเดือน ปี 2026'!T9 -> 0 | O10: ='การลงระหว่างเดือน ปี 2026'!W9 -> 0 | P10: ='การลงระหว่างเดือน ปี 2026'!Z9 -> 0 | Q10: ='การลงระหว่างเดือน ปี 2026'!AC9 -> 0 | R10: ='การลงระหว่างเดือน ปี 2026'!AF9 -> 0 | S10: ='การลงระหว่างเดือน ปี 2026'!AI9 -> 0 | T10: ='การลงระหว่างเดือน ปี 2026'!AL9 -> 0 | U10: =SUM(I10:T10) -> 0 | V10: =I10/$I$18 -> #DIV/0! | W10: =J10/$J$18 -> #DIV/0! | X10: =K10/$K$18 -> #DIV/0! | Y10: =L10/$L$18 -> #DIV/0! | Z10: =M10/$M$18 -> #DIV/0! | AA10: =N10/$N$18 -> #DIV/0! | AB10: =O10/$O$18 -> #DIV/0! | AC10: =P10/$P$18 -> #DIV/0! | AD10: =Q10/$Q$18 -> #DIV/0! | AE10: =R10/$R$18 -> #DIV/0! | AF10: =S10/$S$18 -> #DIV/0! | AG10: =T10/$T$18 -> #DIV/0! | AH10: =U10/$U$18 -> #DIV/0! | AI10: R | AJ10: =IFERROR(U10/E10,0)-1 -> -1
A11: ='งบกำไรขาดทุน ปี 2025'!A11 -> 41200004 | B11: ='งบกำไรขาดทุน ปี 2025'!B11 -> รายได้จากการขาย - Swimming | C11: ='งบกำไรขาดทุน ปี 2025'!O11 -> 0 | D11: =C11/$C$5 -> 0 | E11: =D11*$E$5 -> 0 | F11: =E11/$E$18 -> #DIV/0! | H11: R | I11: ='การลงระหว่างเดือน ปี 2026'!E10 -> 0 | J11: ='การลงระหว่างเดือน ปี 2026'!H10 -> 0 | K11: ='การลงระหว่างเดือน ปี 2026'!K10 -> 0 | L11: ='การลงระหว่างเดือน ปี 2026'!N10 -> 0 | M11: ='การลงระหว่างเดือน ปี 2026'!Q10 -> 0 | N11: ='การลงระหว่างเดือน ปี 2026'!T10 -> 0 | O11: ='การลงระหว่างเดือน ปี 2026'!W10 -> 0 | P11: ='การลงระหว่างเดือน ปี 2026'!Z10 -> 0 | Q11: ='การลงระหว่างเดือน ปี 2026'!AC10 -> 0 | R11: ='การลงระหว่างเดือน ปี 2026'!AF10 -> 0 | S11: ='การลงระหว่างเดือน ปี 2026'!AI10 -> 0 | T11: ='การลงระหว่างเดือน ปี 2026'!AL10 -> 0 | U11: =SUM(I11:T11) -> 0 | V11: =I11/$I$18 -> #DIV/0! | W11: =J11/$J$18 -> #DIV/0! | X11: =K11/$K$18 -> #DIV/0! | Y11: =L11/$L$18 -> #DIV/0! | Z11: =M11/$M$18 -> #DIV/0! | AA11: =N11/$N$18 -> #DIV/0! | AB11: =O11/$O$18 -> #DIV/0! | AC11: =P11/$P$18 -> #DIV/0! | AD11: =Q11/$Q$18 -> #DIV/0! | AE11: =R11/$R$18 -> #DIV/0! | AF11: =S11/$S$18 -> #DIV/0! | AG11: =T11/$T$18 -> #DIV/0! | AH11: =U11/$U$18 -> #DIV/0! | AI11: R | AJ11: =IFERROR(U11/E11,0)-1 -> -1
A12: ='งบกำไรขาดทุน ปี 2025'!A12 -> 41200002 | B12: ='งบกำไรขาดทุน ปี 2025'!B12 -> รายได้จากการขาย - Pettaxi | C12: ='งบกำไรขาดทุน ปี 2025'!O12 -> 0 | D12: =C12/$C$5 -> 0 | E12: =D12*$E$5 -> 0 | F12: =E12/$E$18 -> #DIV/0! | H12: R | I12: ='การลงระหว่างเดือน ปี 2026'!E11 -> 0 | J12: ='การลงระหว่างเดือน ปี 2026'!H11 -> 0 | K12: ='การลงระหว่างเดือน ปี 2026'!K11 -> 0 | L12: ='การลงระหว่างเดือน ปี 2026'!N11 -> 0 | M12: ='การลงระหว่างเดือน ปี 2026'!Q11 -> 0 | N12: ='การลงระหว่างเดือน ปี 2026'!T11 -> 0 | O12: ='การลงระหว่างเดือน ปี 2026'!W11 -> 0 | P12: ='การลงระหว่างเดือน ปี 2026'!Z11 -> 0 | Q12: ='การลงระหว่างเดือน ปี 2026'!AC11 -> 0 | R12: ='การลงระหว่างเดือน ปี 2026'!AF11 -> 0 | S12: ='การลงระหว่างเดือน ปี 2026'!AI11 -> 0 | T12: ='การลงระหว่างเดือน ปี 2026'!AL11 -> 0 | U12: =SUM(I12:T12) -> 0 | V12: =I12/$I$18 -> #DIV/0! | W12: =J12/$J$18 -> #DIV/0! | X12: =K12/$K$18 -> #DIV/0! | Y12: =L12/$L$18 -> #DIV/0! | Z12: =M12/$M$18 -> #DIV/0! | AA12: =N12/$N$18 -> #DIV/0! | AB12: =O12/$O$18 -> #DIV/0! | AC12: =P12/$P$18 -> #DIV/0! | AD12: =Q12/$Q$18 -> #DIV/0! | AE12: =R12/$R$18 -> #DIV/0! | AF12: =S12/$S$18 -> #DIV/0! | AG12: =T12/$T$18 -> #DIV/0! | AH12: =U12/$U$18 -> #DIV/0! | AI12: R | AJ12: =IFERROR(U12/E12,0)-1 -> -1
A13: ='งบกำไรขาดทุน ปี 2025'!A13 -> 41200003 | B13: ='งบกำไรขาดทุน ปี 2025'!B13 -> รายได้จากการขาย - อื่นๆ | C13: ='งบกำไรขาดทุน ปี 2025'!O13 -> 0 | D13: =C13/$C$5 -> 0 | E13: =D13*$E$5 -> 0 | F13: =E13/$E$18 -> #DIV/0! | H13: R | I13: =$D$13 -> 0 | J13: =$D$13 -> 0 | K13: =$D$13 -> 0 | L13: =$D$13 -> 0 | M13: =$D$13 -> 0 | N13: =$D$13 -> 0 | O13: =$D$13 -> 0 | P13: =$D$13 -> 0 | ... T13: =$D$13 -> 0 | U13: =SUM(I13:T13) -> 0 | V13: =I13/$I$18 -> #DIV/0! | W13: =J13/$J$18 -> #DIV/0! | X13: =K13/$K$18 -> #DIV/0! | Y13: =L13/$L$18 -> #DIV/0! | Z13: =M13/$M$18 -> #DIV/0! | AA13: =N13/$N$18 -> #DIV/0! | AB13: =O13/$O$18 -> #DIV/0! | AC13: =P13/$P$18 -> #DIV/0! | AD13: =Q13/$Q$18 -> #DIV/0! | AE13: =R13/$R$18 -> #DIV/0! | AF13: =S13/$S$18 -> #DIV/0! | AG13: =T13/$T$18 -> #DIV/0! | AH13: =U13/$U$18 -> #DIV/0! | AI13: R | AJ13: =IFERROR(U13/E13,0)-1 -> -1
A14: ='งบกำไรขาดทุน ปี 2025'!A14 -> 41300001 | B14: ='งบกำไรขาดทุน ปี 2025'!B14 -> หัก รับคืน | C14: ='งบกำไรขาดทุน ปี 2025'!O14 -> 0 | D14: =C14/$C$5 -> 0 | E14: =D14*$E$5 -> 0 | F14: =E14/$E$18 -> #DIV/0! | H14: R | I14: =$D$14 -> 0 | J14: =$D$14 -> 0 | K14: =$D$14 -> 0 | L14: =$D$14 -> 0 | M14: =$D$14 -> 0 | N14: =$D$14 -> 0 | O14: =$D$14 -> 0 | P14: =$D$14 -> 0 | ... T14: =$D$14 -> 0 | U14: =SUM(I14:T14) -> 0 | V14: =I14/$I$18 -> #DIV/0! | W14: =J14/$J$18 -> #DIV/0! | X14: =K14/$K$18 -> #DIV/0! | Y14: =L14/$L$18 -> #DIV/0! | Z14: =M14/$M$18 -> #DIV/0! | AA14: =N14/$N$18 -> #DIV/0! | AB14: =O14/$O$18 -> #DIV/0! | AC14: =P14/$P$18 -> #DIV/0! | AD14: =Q14/$Q$18 -> #DIV/0! | AE14: =R14/$R$18 -> #DIV/0! | AF14: =S14/$S$18 -> #DIV/0! | AG14: =T14/$T$18 -> #DIV/0! | AH14: =U14/$U$18 -> #DIV/0! | AI14: R | AJ14: =IFERROR(U14/E14,0)-1 -> -1
A15: ='งบกำไรขาดทุน ปี 2025'!A15 -> 41300002 | B15: ='งบกำไรขาดทุน ปี 2025'!B15 -> หัก ส่วนลดจ่าย | C15: ='งบกำไรขาดทุน ปี 2025'!O15 -> 0 | D15: =C15/$C$5 -> 0 | E15: =D15*$E$5 -> 0 | F15: =E15/$E$18 -> #DIV/0! | H15: R | I15: =$D$15 -> 0 | J15: =$D$15 -> 0 | K15: =$D$15 -> 0 | L15: =$D$15 -> 0 | M15: =$D$15 -> 0 | N15: =$D$15 -> 0 | O15: =$D$15 -> 0 | P15: =$D$15 -> 0 | ... T15: =$D$15 -> 0 | U15: =SUM(I15:T15) -> 0 | V15: =I15/$I$18 -> #DIV/0! | W15: =J15/$J$18 -> #DIV/0! | X15: =K15/$K$18 -> #DIV/0! | Y15: =L15/$L$18 -> #DIV/0! | Z15: =M15/$M$18 -> #DIV/0! | AA15: =N15/$N$18 -> #DIV/0! | AB15: =O15/$O$18 -> #DIV/0! | AC15: =P15/$P$18 -> #DIV/0! | AD15: =Q15/$Q$18 -> #DIV/0! | AE15: =R15/$R$18 -> #DIV/0! | AF15: =S15/$S$18 -> #DIV/0! | AG15: =T15/$T$18 -> #DIV/0! | AH15: =U15/$U$18 -> #DIV/0! | AI15: R | AJ15: =IFERROR(U15/E15,0)-1 -> -1
A16: ='งบกำไรขาดทุน ปี 2025'!A16 -> 42000001 | B16: ='งบกำไรขาดทุน ปี 2025'!B16 -> รายได้อื่นๆ | C16: ='งบกำไรขาดทุน ปี 2025'!O16 -> 0 | D16: =C16/$C$5 -> 0 | E16: =D16*$E$5 -> 0 | F16: =E16/$E$18 -> #DIV/0! | H16: R | I16: =$D$16 -> 0 | J16: =$D$16 -> 0 | K16: =$D$16 -> 0 | L16: =$D$16 -> 0 | M16: =$D$16 -> 0 | N16: =$D$16 -> 0 | O16: =$D$16 -> 0 | P16: =$D$16 -> 0 | ... T16: =$D$16 -> 0 | U16: =SUM(I16:T16) -> 0 | V16: =I16/$I$18 -> #DIV/0! | W16: =J16/$J$18 -> #DIV/0! | X16: =K16/$K$18 -> #DIV/0! | Y16: =L16/$L$18 -> #DIV/0! | Z16: =M16/$M$18 -> #DIV/0! | AA16: =N16/$N$18 -> #DIV/0! | AB16: =O16/$O$18 -> #DIV/0! | AC16: =P16/$P$18 -> #DIV/0! | AD16: =Q16/$Q$18 -> #DIV/0! | AE16: =R16/$R$18 -> #DIV/0! | AF16: =S16/$S$18 -> #DIV/0! | AG16: =T16/$T$18 -> #DIV/0! | AH16: =U16/$U$18 -> #DIV/0! | AI16: R | AJ16: =IFERROR(U16/E16,0)-1 -> -1
A17: ='งบกำไรขาดทุน ปี 2025'!A17 -> 42000019 | B17: ='งบกำไรขาดทุน ปี 2025'!B17 -> รายได้ Package/PR/ขนส่ง | C17: ='งบกำไรขาดทุน ปี 2025'!O17 -> 0 | D17: =C17/$C$5 -> 0 | E17: =D17*$E$5 -> 0 | F17: =E17/$E$18 -> #DIV/0! | H17: R | I17: =$D$16 -> 0 | J17: =$D$16 -> 0 | K17: =$D$16 -> 0 | L17: =$D$16 -> 0 | M17: =$D$16 -> 0 | N17: =$D$16 -> 0 | O17: =$D$16 -> 0 | P17: =$D$16 -> 0 | ... T17: =$D$16 -> 0 | U17: =SUM(I17:T17) -> 0 | V17: =I17/$I$18 -> #DIV/0! | W17: =J17/$J$18 -> #DIV/0! | X17: =K17/$K$18 -> #DIV/0! | Y17: =L17/$L$18 -> #DIV/0! | Z17: =M17/$M$18 -> #DIV/0! | AA17: =N17/$N$18 -> #DIV/0! | AB17: =O17/$O$18 -> #DIV/0! | AC17: =P17/$P$18 -> #DIV/0! | AD17: =Q17/$Q$18 -> #DIV/0! | AE17: =R17/$R$18 -> #DIV/0! | AF17: =S17/$S$18 -> #DIV/0! | AG17: =T17/$T$18 -> #DIV/0! | AH17: =U17/$U$18 -> #DIV/0! | AI17: R | AJ17: =IFERROR(U17/E17,0)-1 -> -1
A18: ='งบกำไรขาดทุน ปี 2025'!A18 -> 0 | B18: ='งบกำไรขาดทุน ปี 2025'!B18 -> รวมรายได้จาการขายและอื่นๆ | C18: ='งบกำไรขาดทุน ปี 2025'!O18 -> 0 | D18: =C18/$C$5 -> 0 | E18: =D18*$E$5 -> 0 | F18: =E18/$E$18 -> #DIV/0! | I18: =SUM(I8:I16) -> 0 | J18: =SUM(J8:J16) -> 0 | K18: =SUM(K8:K16) -> 0 | L18: =SUM(L8:L16) -> 0 | M18: =SUM(M8:M16) -> 0 | N18: =SUM(N8:N16) -> 0 | O18: =SUM(O8:O16) -> 0 | P18: =SUM(P8:P16) -> 0 | ... U18: =SUM(U8:U16) -> 0 | V18: =I18/$I$18 -> #DIV/0! | W18: =J18/$J$18 -> #DIV/0! | X18: =K18/$K$18 -> #DIV/0! | Y18: =L18/$L$18 -> #DIV/0! | Z18: =M18/$M$18 -> #DIV/0! | AA18: =N18/$N$18 -> #DIV/0! | AB18: =O18/$O$18 -> #DIV/0! | AC18: =P18/$P$18 -> #DIV/0! | AD18: =Q18/$Q$18 -> #DIV/0! | AE18: =R18/$R$18 -> #DIV/0! | AF18: =S18/$S$18 -> #DIV/0! | AG18: =T18/$T$18 -> #DIV/0! | AH18: =U18/$U$18 -> #DIV/0! | AJ18: =IFERROR(U18/E18,0)-1 -> -1
A19: ='งบกำไรขาดทุน ปี 2025'!A19 -> 0 | B19: ='งบกำไรขาดทุน ปี 2025'!B19 -> ต้นทุนขายและค่าใช้จ่ายที่เกี่ยวข้อง | C19: ='งบกำไรขาดทุน ปี 2025'!O19 -> 0 | AJ19: =IFERROR(U19/E19,0)-1 -> -1
A20: ='งบกำไรขาดทุน ปี 2025'!A20 -> 0 | B20: ='งบกำไรขาดทุน ปี 2025'!B20 -> ต้นทุนขาย | C20: ='งบกำไรขาดทุน ปี 2025'!O20 -> 0 | AJ20: =IFERROR(U20/E20,0)-1 -> -1
A21: ='งบกำไรขาดทุน ปี 2025'!A21 -> 51000002 | B21: ='งบกำไรขาดทุน ปี 2025'!B21 -> ต้นทุนขายสินค้า PH | C21: ='งบกำไรขาดทุน ปี 2025'!O21 -> 0 | D21: =C21/$C$5 -> 0 | E21: =D21*$E$5 -> 0 | F21: =(E21+E23)/(E8+E9+E11+E12+E13) -> #DIV/0! | G21: -0.0075 | H21: C | I21: =((I8+I9+I11+I12+I13)*(F21+G21)) -> #DIV/0! | J21: =($J$18*(F21+G21)) -> #DIV/0! | K21: =($K$18*(F21+G21)) -> #DIV/0! | L21: =($L$18*(F21+G21)) -> #DIV/0! | M21: =($M$18*(F21+G21)) -> #DIV/0! | N21: =($N$18*(F21+G21)) -> #DIV/0! | O21: =($O$18*(F21+G21)) -> #DIV/0! | P21: =($P$18*(F21+G21)) -> #DIV/0! | Q21: =($Q$18*(F21+G21)) -> #DIV/0! | R21: =($R$18*(F21+G21)) -> #DIV/0! | S21: =($S$18*(F21+G21)) -> #DIV/0! | T21: =($T$18*(F21+G21)) -> #DIV/0! | U21: =SUM(I21:T21) -> #DIV/0! | V21: =I21/$I$18 -> #DIV/0! | W21: =J21/$J$18 -> #DIV/0! | X21: =K21/$K$18 -> #DIV/0! | Y21: =L21/$L$18 -> #DIV/0! | Z21: =M21/$M$18 -> #DIV/0! | AA21: =N21/$N$18 -> #DIV/0! | AB21: =O21/$O$18 -> #DIV/0! | AC21: =P21/$P$18 -> #DIV/0! | AD21: =Q21/$Q$18 -> #DIV/0! | AE21: =R21/$R$18 -> #DIV/0! | AF21: =S21/$S$18 -> #DIV/0! | AG21: =T21/$T$18 -> #DIV/0! | AH21: =U21/(U8+U9+U11+U12+U13) -> #DIV/0! | AJ21: =IFERROR(U21/E21,0)-1 -> -1
A22: ='งบกำไรขาดทุน ปี 2025'!A22 -> 51000003 | B22: ='งบกำไรขาดทุน ปี 2025'!B22 -> ต้นทุนขายสินค้า PC | C22: ='งบกำไรขาดทุน ปี 2025'!O22 -> 0 | D22: =C22/$C$5 -> 0 | E22: =D22*$E$5 -> 0 | F22: =E22/$E$10 -> #DIV/0! | G22: -0.015 | H22: C | I22: =(I10*($F$22+$G$22)) -> #DIV/0! | J22: =(J10*($F$22+$G$22)) -> #DIV/0! | K22: =(K10*($F$22+$G$22)) -> #DIV/0! | L22: =(L10*($F$22+$G$22)) -> #DIV/0! | M22: =(M10*($F$22+$G$22)) -> #DIV/0! | N22: =(N10*($F$22+$G$22)) -> #DIV/0! | O22: =(O10*($F$22+$G$22)) -> #DIV/0! | P22: =(P10*($F$22+$G$22)) -> #DIV/0! | ... T22: =(T10*($F$22+$G$22)) -> #DIV/0! | U22: =SUM(I22:T22) -> #DIV/0! | V22: =I22/$I$18 -> #DIV/0! | W22: =J22/$J$18 -> #DIV/0! | X22: =K22/$K$18 -> #DIV/0! | Y22: =L22/$L$18 -> #DIV/0! | Z22: =M22/$M$18 -> #DIV/0! | AA22: =N22/$N$18 -> #DIV/0! | AB22: =O22/$O$18 -> #DIV/0! | AC22: =P22/$P$18 -> #DIV/0! | AD22: =Q22/$Q$18 -> #DIV/0! | AE22: =R22/$R$18 -> #DIV/0! | AF22: =S22/$S$18 -> #DIV/0! | AG22: =T22/$T$18 -> #DIV/0! | AH22: =U22/$U$10 -> #DIV/0! | AJ22: =IFERROR(U22/E22,0)-1 -> -1
A23: ='งบกำไรขาดทุน ปี 2025'!A23 -> 51000004 | B23: ='งบกำไรขาดทุน ปี 2025'!B23 -> หัก ส่วนลดรับ | C23: ='งบกำไรขาดทุน ปี 2025'!O23 -> 0 | D23: =C23/$C$5 -> 0 | E23: =D23*$E$5 -> 0 | F23: =(E23)/(E8+E9+E11+E12+E13) -> #DIV/0! | G23: 0 | H23: C | I23: =($I$18*(F23+G23)) -> #DIV/0! | J23: =($J$18*(F23+G23)) -> #DIV/0! | K23: =($K$18*(F23+G23)) -> #DIV/0! | L23: =($L$18*(F23+G23)) -> #DIV/0! | M23: =($M$18*(F23+G23)) -> #DIV/0! | N23: =($N$18*(F23+G23)) -> #DIV/0! | O23: =($O$18*(F23+G23)) -> #DIV/0! | P23: =($P$18*(F23+G23)) -> #DIV/0! | Q23: =($Q$18*(F23+G23)) -> #DIV/0! | R23: =($R$18*(F23+G23)) -> #DIV/0! | S23: =($S$18*(F23+G23)) -> #DIV/0! | T23: =($T$18*(F23+G23)) -> #DIV/0! | U23: =SUM(I23:T23) -> #DIV/0! | V23: =I23/$I$18 -> #DIV/0! | W23: =J23/$J$18 -> #DIV/0! | X23: =K23/$K$18 -> #DIV/0! | Y23: =L23/$L$18 -> #DIV/0! | Z23: =M23/$M$18 -> #DIV/0! | AA23: =N23/$N$18 -> #DIV/0! | AB23: =O23/$O$18 -> #DIV/0! | AC23: =P23/$P$18 -> #DIV/0! | AD23: =Q23/$Q$18 -> #DIV/0! | AE23: =R23/$R$18 -> #DIV/0! | AF23: =S23/$S$18 -> #DIV/0! | AG23: =T23/$T$18 -> #DIV/0! | AH23: =U23/(U8+U9+U11+U13+U14) -> #DIV/0! | AJ23: =IFERROR(U23/E23,0)-1 -> -1
A24: ='งบกำไรขาดทุน ปี 2025'!A24 -> 51000001 | B24: ='งบกำไรขาดทุน ปี 2025'!B24 -> รวมต้นทุนขาย | C24: ='งบกำไรขาดทุน ปี 2025'!O24 -> 0 | D24: =C24/$C$5 -> 0 | E24: =D24*$E$5 -> 0 | F24: =E24/$E$18 -> #DIV/0! | H24: c | I24: =SUM(I20:I23) -> #DIV/0! | J24: =SUM(J20:J23) -> #DIV/0! | K24: =SUM(K20:K23) -> #DIV/0! | L24: =SUM(L20:L23) -> #DIV/0! | M24: =SUM(M20:M23) -> #DIV/0! | N24: =SUM(N20:N23) -> #DIV/0! | O24: =SUM(O20:O23) -> #DIV/0! | P24: =SUM(P20:P23) -> #DIV/0! | ... T24: =SUM(T20:T23) -> #DIV/0! | U24: =SUM(U19:U23) -> #DIV/0! | V24: =I24/$I$18 -> #DIV/0! | W24: =J24/$J$18 -> #DIV/0! | X24: =K24/$K$18 -> #DIV/0! | Y24: =L24/$L$18 -> #DIV/0! | Z24: =M24/$M$18 -> #DIV/0! | AA24: =N24/$N$18 -> #DIV/0! | AB24: =O24/$O$18 -> #DIV/0! | AC24: =P24/$P$18 -> #DIV/0! | AD24: =Q24/$Q$18 -> #DIV/0! | AE24: =R24/$R$18 -> #DIV/0! | AF24: =S24/$S$18 -> #DIV/0! | AG24: =T24/$T$18 -> #DIV/0! | AH24: =U24/$U$18 -> #DIV/0! | AI24: c | AJ24: =IFERROR(U24/E24,0)-1 -> -1
A25: ='งบกำไรขาดทุน ปี 2025'!A25 -> 0 | B25: ='งบกำไรขาดทุน ปี 2025'!B25 -> ค่าใช้จ่ายในการขาย | F25: =E25/$E$18 -> #DIV/0! | AJ25: =IFERROR(U25/E25,0)-1 -> -1
A26: ='งบกำไรขาดทุน ปี 2025'!A26 -> 52000017 | B26: ='งบกำไรขาดทุน ปี 2025'!B26 -> ค่าใช้จ่ายในการขาย และค่าธรรมเนียม | C26: ='งบกำไรขาดทุน ปี 2025'!O26 -> 0 | D26: =C26/$C$5 -> 0 | E26: =D26*$E$5 -> 0 | F26: =E26/$E$18 -> #DIV/0! | H26: V | I26: =((I$18*($F26+$G26))) -> #DIV/0! | J26: =((J$18*($F26+$G26))+'การลงระหว่างเดือน ปี 2026'!AP13) -> #DIV/0! | K26: =((K$18*($F26+$G26))+'การลงระหว่างเดือน ปี 2026'!AQ13) -> #DIV/0! | L26: =((L$18*($F26+$G26))+'การลงระหว่างเดือน ปี 2026'!AR13) -> #DIV/0! | M26: =((M$18*($F26+$G26))+'การลงระหว่างเดือน ปี 2026'!AS13) -> #DIV/0! | N26: =((N$18*($F26+$G26))+'การลงระหว่างเดือน ปี 2026'!AT13) -> #DIV/0! | O26: =((O$18*($F26+$G26))+'การลงระหว่างเดือน ปี 2026'!AU13) -> #DIV/0! | P26: =((P$18*($F26+$G26))+'การลงระหว่างเดือน ปี 2026'!AV13) -> #DIV/0! | Q26: =((Q$18*($F26+$G26))+'การลงระหว่างเดือน ปี 2026'!AW13) -> #DIV/0! | ... T26: =((T$18*($F26+$G26))+'การลงระหว่างเดือน ปี 2026'!AZ13) -> #DIV/0! | U26: =SUM(I26:T26) -> #DIV/0! | V26: =I26/$I$18 -> #DIV/0! | W26: =J26/$J$18 -> #DIV/0! | X26: =K26/$K$18 -> #DIV/0! | Y26: =L26/$L$18 -> #DIV/0! | Z26: =M26/$M$18 -> #DIV/0! | AA26: =N26/$N$18 -> #DIV/0! | AB26: =O26/$O$18 -> #DIV/0! | AC26: =P26/$P$18 -> #DIV/0! | AD26: =Q26/$Q$18 -> #DIV/0! | AE26: =R26/$R$18 -> #DIV/0! | AF26: =S26/$S$18 -> #DIV/0! | AG26: =T26/$T$18 -> #DIV/0! | AH26: =U26/$U$18 -> #DIV/0! | AI26: V | AJ26: =IFERROR(U26/E26,0)-1 -> -1
A27: ='งบกำไรขาดทุน ปี 2025'!A27 -> 52000001 | B27: ='งบกำไรขาดทุน ปี 2025'!B27 -> ค่าส่งเสริมการขาย | C27: ='งบกำไรขาดทุน ปี 2025'!O27 -> 0 | D27: =C27/$C$5 -> 0 | E27: =D27*$E$5 -> 0 | F27: =E27/$E$18 -> #DIV/0! | H27: Z | I27: ='การลงระหว่างเดือน ปี 2026'!AO13 -> 0 | J27: ='การลงระหว่างเดือน ปี 2026'!AP13 -> 0 | K27: ='การลงระหว่างเดือน ปี 2026'!AQ13 -> 0 | L27: ='การลงระหว่างเดือน ปี 2026'!AR13 -> 0 | M27: ='การลงระหว่างเดือน ปี 2026'!AS13 -> 0 | N27: ='การลงระหว่างเดือน ปี 2026'!AT13 -> 0 | O27: ='การลงระหว่างเดือน ปี 2026'!AU13 -> 0 | P27: ='การลงระหว่างเดือน ปี 2026'!AV13 -> 0 | ... T27: ='การลงระหว่างเดือน ปี 2026'!AZ13 -> 0 | U27: =SUM(I27:T27) -> 0 | V27: =I27/$I$18 -> #DIV/0! | W27: =J27/$J$18 -> #DIV/0! | X27: =K27/$K$18 -> #DIV/0! | Y27: =L27/$L$18 -> #DIV/0! | Z27: =M27/$M$18 -> #DIV/0! | AA27: =N27/$N$18 -> #DIV/0! | AB27: =O27/$O$18 -> #DIV/0! | AC27: =P27/$P$18 -> #DIV/0! | AD27: =Q27/$Q$18 -> #DIV/0! | AE27: =R27/$R$18 -> #DIV/0! | AF27: =S27/$S$18 -> #DIV/0! | AG27: =T27/$T$18 -> #DIV/0! | AH27: =U27/$U$18 -> #DIV/0! | AI27: V | AJ27: =IFERROR(U27/E27,0)-1 -> -1
A28: ='งบกำไรขาดทุน ปี 2025'!A28 -> 52000003 | B28: ='งบกำไรขาดทุน ปี 2025'!B28 -> ค่าชันสูตรโรค | C28: ='งบกำไรขาดทุน ปี 2025'!O28 -> 0 | D28: =C28/$C$5 -> 0 | E28: =D28*$E$5 -> 0 | F28: =E28/$E$18 -> #DIV/0! | H28: V | I28: =((I$18*($F28+$G28))) -> #DIV/0! | J28: =((J$18*($F28+$G28))) -> #DIV/0! | K28: =((K$18*($F28+$G28))) -> #DIV/0! | L28: =((L$18*($F28+$G28))) -> #DIV/0! | M28: =((M$18*($F28+$G28))) -> #DIV/0! | N28: =((N$18*($F28+$G28))) -> #DIV/0! | O28: =((O$18*($F28+$G28))) -> #DIV/0! | P28: =((P$18*($F28+$G28))) -> #DIV/0! | ... T28: =((T$18*($F28+$G28))) -> #DIV/0! | U28: =SUM(I28:T28) -> #DIV/0! | V28: =I28/$I$18 -> #DIV/0! | W28: =J28/$J$18 -> #DIV/0! | X28: =K28/$K$18 -> #DIV/0! | Y28: =L28/$L$18 -> #DIV/0! | Z28: =M28/$M$18 -> #DIV/0! | AA28: =N28/$N$18 -> #DIV/0! | AB28: =O28/$O$18 -> #DIV/0! | AC28: =P28/$P$18 -> #DIV/0! | AD28: =Q28/$Q$18 -> #DIV/0! | AE28: =R28/$R$18 -> #DIV/0! | AF28: =S28/$S$18 -> #DIV/0! | AG28: =T28/$T$18 -> #DIV/0! | AH28: =U28/$U$18 -> #DIV/0! | AI28: V | AJ28: =IFERROR(U28/E28,0)-1 -> -1
A29: ='งบกำไรขาดทุน ปี 2025'!A29 -> 52000004 | B29: ='งบกำไรขาดทุน ปี 2025'!B29 -> ค่าส่งเผา | C29: ='งบกำไรขาดทุน ปี 2025'!O29 -> 0 | D29: =C29/$C$5 -> 0 | E29: =D29*$E$5 -> 0 | F29: =E29/$E$18 -> #DIV/0! | H29: V | I29: =((I$18*($F29+$G29))) -> #DIV/0! | J29: =((J$18*($F29+$G29))) -> #DIV/0! | K29: =((K$18*($F29+$G29))) -> #DIV/0! | L29: =((L$18*($F29+$G29))) -> #DIV/0! | M29: =((M$18*($F29+$G29))) -> #DIV/0! | N29: =((N$18*($F29+$G29))) -> #DIV/0! | O29: =((O$18*($F29+$G29))) -> #DIV/0! | P29: =((P$18*($F29+$G29))) -> #DIV/0! | ... T29: =((T$18*($F29+$G29))) -> #DIV/0! | U29: =SUM(I29:T29) -> #DIV/0! | V29: =I29/$I$18 -> #DIV/0! | W29: =J29/$J$18 -> #DIV/0! | X29: =K29/$K$18 -> #DIV/0! | Y29: =L29/$L$18 -> #DIV/0! | Z29: =M29/$M$18 -> #DIV/0! | AA29: =N29/$N$18 -> #DIV/0! | AB29: =O29/$O$18 -> #DIV/0! | AC29: =P29/$P$18 -> #DIV/0! | AD29: =Q29/$Q$18 -> #DIV/0! | AE29: =R29/$R$18 -> #DIV/0! | AF29: =S29/$S$18 -> #DIV/0! | AG29: =T29/$T$18 -> #DIV/0! | AH29: =U29/$U$18 -> #DIV/0! | AI29: V | AJ29: =IFERROR(U29/E29,0)-1 -> -1
A30: ='งบกำไรขาดทุน ปี 2025'!A30 -> 52000005 | B30: ='งบกำไรขาดทุน ปี 2025'!B30 -> ค่าตรวจเลือด | C30: ='งบกำไรขาดทุน ปี 2025'!O30 -> 0 | D30: =C30/$C$5 -> 0 | E30: =D30*$E$5 -> 0 | F30: =E30/$E$18 -> #DIV/0! | H30: V | I30: =((I$18*($F30+$G30))) -> #DIV/0! | J30: =((J$18*($F30+$G30))) -> #DIV/0! | K30: =((K$18*($F30+$G30))) -> #DIV/0! | L30: =((L$18*($F30+$G30))) -> #DIV/0! | M30: =((M$18*($F30+$G30))) -> #DIV/0! | N30: =((N$18*($F30+$G30))) -> #DIV/0! | O30: =((O$18*($F30+$G30))) -> #DIV/0! | P30: =((P$18*($F30+$G30))) -> #DIV/0! | ... T30: =((T$18*($F30+$G30))) -> #DIV/0! | U30: =SUM(I30:T30) -> #DIV/0! | V30: =I30/$I$18 -> #DIV/0! | W30: =J30/$J$18 -> #DIV/0! | X30: =K30/$K$18 -> #DIV/0! | Y30: =L30/$L$18 -> #DIV/0! | Z30: =M30/$M$18 -> #DIV/0! | AA30: =N30/$N$18 -> #DIV/0! | AB30: =O30/$O$18 -> #DIV/0! | AC30: =P30/$P$18 -> #DIV/0! | AD30: =Q30/$Q$18 -> #DIV/0! | AE30: =R30/$R$18 -> #DIV/0! | AF30: =S30/$S$18 -> #DIV/0! | AG30: =T30/$T$18 -> #DIV/0! | AH30: =U30/$U$18 -> #DIV/0! | AI30: V | AJ30: =IFERROR(U30/E30,0)-1 -> -1
A31: ='งบกำไรขาดทุน ปี 2025'!A31 -> 52000006 | B31: ='งบกำไรขาดทุน ปี 2025'!B31 -> ค่าตรวจเลือดภายใน | C31: ='งบกำไรขาดทุน ปี 2025'!O31 -> 0 | D31: =C31/$C$5 -> 0 | E31: =D31*$E$5 -> 0 | F31: =E31/$E$18 -> #DIV/0! | H31: V | I31: =((I$18*($F31+$G31))) -> #DIV/0! | J31: =((J$18*($F31+$G31))) -> #DIV/0! | K31: =((K$18*($F31+$G31))) -> #DIV/0! | L31: =((L$18*($F31+$G31))) -> #DIV/0! | M31: =((M$18*($F31+$G31))) -> #DIV/0! | N31: =((N$18*($F31+$G31))) -> #DIV/0! | O31: =((O$18*($F31+$G31))) -> #DIV/0! | P31: =((P$18*($F31+$G31))) -> #DIV/0! | ... T31: =((T$18*($F31+$G31))) -> #DIV/0! | U31: =SUM(I31:T31) -> #DIV/0! | V31: =I31/$I$18 -> #DIV/0! | W31: =J31/$J$18 -> #DIV/0! | X31: =K31/$K$18 -> #DIV/0! | Y31: =L31/$L$18 -> #DIV/0! | Z31: =M31/$M$18 -> #DIV/0! | AA31: =N31/$N$18 -> #DIV/0! | AB31: =O31/$O$18 -> #DIV/0! | AC31: =P31/$P$18 -> #DIV/0! | AD31: =Q31/$Q$18 -> #DIV/0! | AE31: =R31/$R$18 -> #DIV/0! | AF31: =S31/$S$18 -> #DIV/0! | AG31: =T31/$T$18 -> #DIV/0! | AH31: =U31/$U$18 -> #DIV/0! | AI31: V | AJ31: =IFERROR(U31/E31,0)-1 -> -1
A32: ='งบกำไรขาดทุน ปี 2025'!A32 -> 52000007 | B32: ='งบกำไรขาดทุน ปี 2025'!B32 -> ค่าเช่าเครื่องมือภายใน | C32: ='งบกำไรขาดทุน ปี 2025'!O32 -> 0 | D32: =C32/$C$5 -> 0 | E32: =D32*$E$5 -> 0 | F32: =E32/$E$18 -> #DIV/0! | H32: V | I32: =((I$18*($F32+$G32))) -> #DIV/0! | J32: =((J$18*($F32+$G32))) -> #DIV/0! | K32: =((K$18*($F32+$G32))) -> #DIV/0! | L32: =((L$18*($F32+$G32))) -> #DIV/0! | M32: =((M$18*($F32+$G32))) -> #DIV/0! | N32: =((N$18*($F32+$G32))) -> #DIV/0! | O32: =((O$18*($F32+$G32))) -> #DIV/0! | P32: =((P$18*($F32+$G32))) -> #DIV/0! | ... T32: =((T$18*($F32+$G32))) -> #DIV/0! | U32: =SUM(I32:T32) -> #DIV/0! | V32: =I32/$I$18 -> #DIV/0! | W32: =J32/$J$18 -> #DIV/0! | X32: =K32/$K$18 -> #DIV/0! | Y32: =L32/$L$18 -> #DIV/0! | Z32: =M32/$M$18 -> #DIV/0! | AA32: =N32/$N$18 -> #DIV/0! | AB32: =O32/$O$18 -> #DIV/0! | AC32: =P32/$P$18 -> #DIV/0! | AD32: =Q32/$Q$18 -> #DIV/0! | AE32: =R32/$R$18 -> #DIV/0! | AF32: =S32/$S$18 -> #DIV/0! | AG32: =T32/$T$18 -> #DIV/0! | AH32: =U32/$U$18 -> #DIV/0! | AI32: V | AJ32: =IFERROR(U32/E32,0)-1 -> -1
A33: ='งบกำไรขาดทุน ปี 2025'!A33 -> 52000008 | B33: ='งบกำไรขาดทุน ปี 2025'!B33 -> ค่าบริการวิชาชีพแพทย์ | C33: ='งบกำไรขาดทุน ปี 2025'!O33 -> 0 | D33: =C33/$C$5 -> 0 | E33: =D33*$E$5 -> 0 | F33: =E33/$E$18 -> #DIV/0! | H33: V | I33: =((I$18*($F33+$G33))+'การลงระหว่างเดือน ปี 2026'!AO14) -> #DIV/0! | J33: =((J$18*($F33+$G33))+'การลงระหว่างเดือน ปี 2026'!AP14) -> #DIV/0! | K33: =((K$18*($F33+$G33))+'การลงระหว่างเดือน ปี 2026'!AQ14) -> #DIV/0! | L33: =((L$18*($F33+$G33))+'การลงระหว่างเดือน ปี 2026'!AR14) -> #DIV/0! | M33: =((M$18*($F33+$G33))+'การลงระหว่างเดือน ปี 2026'!AS14) -> #DIV/0! | N33: =((N$18*($F33+$G33))+'การลงระหว่างเดือน ปี 2026'!AT14) -> #DIV/0! | O33: =((O$18*($F33+$G33))+'การลงระหว่างเดือน ปี 2026'!AU14) -> #DIV/0! | P33: =((P$18*($F33+$G33))+'การลงระหว่างเดือน ปี 2026'!AV14) -> #DIV/0! | ... T33: =((T$18*($F33+$G33))+'การลงระหว่างเดือน ปี 2026'!AZ14) -> #DIV/0! | U33: =SUM(I33:T33) -> #DIV/0! | V33: =I33/$I$18 -> #DIV/0! | W33: =J33/$J$18 -> #DIV/0! | X33: =K33/$K$18 -> #DIV/0! | Y33: =L33/$L$18 -> #DIV/0! | Z33: =M33/$M$18 -> #DIV/0! | AA33: =N33/$N$18 -> #DIV/0! | AB33: =O33/$O$18 -> #DIV/0! | AC33: =P33/$P$18 -> #DIV/0! | AD33: =Q33/$Q$18 -> #DIV/0! | AE33: =R33/$R$18 -> #DIV/0! | AF33: =S33/$S$18 -> #DIV/0! | AG33: =T33/$T$18 -> #DIV/0! | AH33: =U33/$U$18 -> #DIV/0! | AI33: V | AJ33: =IFERROR(U33/E33,0)-1 -> -1
A34: ='งบกำไรขาดทุน ปี 2025'!A34 -> 52000010 | B34: ='งบกำไรขาดทุน ปี 2025'!B34 -> ค่าเช่าเครื่องมือแพทย์ | C34: ='งบกำไรขาดทุน ปี 2025'!O34 -> 0 | D34: =C34/$C$5 -> 0 | E34: =D34*$E$5 -> 0 | F34: =E34/$E$18 -> #DIV/0! | G34: =$U$2 -> #DIV/0! | H34: F | I34: =(($D34*$G34)+$D34)+'การลงระหว่างเดือน ปี 2026'!AO15 -> #DIV/0! | J34: =(($D34*$G34)+$D34)+'การลงระหว่างเดือน ปี 2026'!AP15 -> #DIV/0! | K34: =(($D34*$G34)+$D34)+'การลงระหว่างเดือน ปี 2026'!AQ15 -> #DIV/0! | L34: =(($D34*$G34)+$D34)+'การลงระหว่างเดือน ปี 2026'!AR15 -> #DIV/0! | M34: =(($D34*$G34)+$D34)+'การลงระหว่างเดือน ปี 2026'!AS15 -> #DIV/0! | N34: =(($D34*$G34)+$D34)+'การลงระหว่างเดือน ปี 2026'!AT15 -> #DIV/0! | O34: =(($D34*$G34)+$D34)+'การลงระหว่างเดือน ปี 2026'!AU15 -> #DIV/0! | P34: =(($D34*$G34)+$D34)+'การลงระหว่างเดือน ปี 2026'!AV15 -> #DIV/0! | ... T34: =(($D34*$G34)+$D34)+'การลงระหว่างเดือน ปี 2026'!AZ15 -> #DIV/0! | U34: =SUM(I34:T34) -> #DIV/0! | V34: =I34/$I$18 -> #DIV/0! | W34: =J34/$J$18 -> #DIV/0! | X34: =K34/$K$18 -> #DIV/0! | Y34: =L34/$L$18 -> #DIV/0! | Z34: =M34/$M$18 -> #DIV/0! | AA34: =N34/$N$18 -> #DIV/0! | AB34: =O34/$O$18 -> #DIV/0! | AC34: =P34/$P$18 -> #DIV/0! | AD34: =Q34/$Q$18 -> #DIV/0! | AE34: =R34/$R$18 -> #DIV/0! | AF34: =S34/$S$18 -> #DIV/0! | AG34: =T34/$T$18 -> #DIV/0! | AH34: =U34/$U$18 -> #DIV/0! | AI34: F | AJ34: =IFERROR(U34/E34,0)-1 -> -1
A35: ='งบกำไรขาดทุน ปี 2025'!A35 -> 52000011 | B35: ='งบกำไรขาดทุน ปี 2025'!B35 -> ค่าวัสดุเครื่องมือแพทย์ | C35: ='งบกำไรขาดทุน ปี 2025'!O35 -> 0 | D35: =C35/$C$5 -> 0 | E35: =D35*$E$5 -> 0 | F35: =E35/$E$18 -> #DIV/0! | H35: V | I35: =((I$18*($F35+$G35))+'การลงระหว่างเดือน ปี 2026'!AO16) -> #DIV/0! | J35: =((J$18*($F35+$G35))+'การลงระหว่างเดือน ปี 2026'!AP16) -> #DIV/0! | K35: =((K$18*($F35+$G35))+'การลงระหว่างเดือน ปี 2026'!AQ16) -> #DIV/0! | L35: =((L$18*($F35+$G35))+'การลงระหว่างเดือน ปี 2026'!AR16) -> #DIV/0! | M35: =((M$18*($F35+$G35))+'การลงระหว่างเดือน ปี 2026'!AS16) -> #DIV/0! | N35: =((N$18*($F35+$G35))+'การลงระหว่างเดือน ปี 2026'!AT16) -> #DIV/0! | O35: =((O$18*($F35+$G35))+'การลงระหว่างเดือน ปี 2026'!AU16) -> #DIV/0! | P35: =((P$18*($F35+$G35))+'การลงระหว่างเดือน ปี 2026'!AV16) -> #DIV/0! | ... T35: =((T$18*($F35+$G35))+'การลงระหว่างเดือน ปี 2026'!AZ16) -> #DIV/0! | U35: =SUM(I35:T35) -> #DIV/0! | V35: =I35/$I$18 -> #DIV/0! | W35: =J35/$J$18 -> #DIV/0! | X35: =K35/$K$18 -> #DIV/0! | Y35: =L35/$L$18 -> #DIV/0! | Z35: =M35/$M$18 -> #DIV/0! | AA35: =N35/$N$18 -> #DIV/0! | AB35: =O35/$O$18 -> #DIV/0! | AC35: =P35/$P$18 -> #DIV/0! | AD35: =Q35/$Q$18 -> #DIV/0! | AE35: =R35/$R$18 -> #DIV/0! | AF35: =S35/$S$18 -> #DIV/0! | AG35: =T35/$T$18 -> #DIV/0! | AH35: =U35/$U$18 -> #DIV/0! | AI35: V | AJ35: =IFERROR(U35/E35,0)-1 -> -1
A36: ='งบกำไรขาดทุน ปี 2025'!A36 -> 52000014 | B36: ='งบกำไรขาดทุน ปี 2025'!B36 -> ค่าเช่าอุปกรณ์-เครื่องมือระหว่างสาขา | C36: ='งบกำไรขาดทุน ปี 2025'!O36 -> 0 | D36: =C36/$C$5 -> 0 | E36: =D36*$E$5 -> 0 | F36: =E36/$E$18 -> #DIV/0! | H36: F | I36: =(($D36*$G36)+$D36)+'การลงระหว่างเดือน ปี 2026'!AO17 -> 0 | J36: =(($D36*$G36)+$D36)+'การลงระหว่างเดือน ปี 2026'!AP17 -> 0 | K36: =(($D36*$G36)+$D36)+'การลงระหว่างเดือน ปี 2026'!AQ17 -> 0 | L36: =(($D36*$G36)+$D36)+'การลงระหว่างเดือน ปี 2026'!AR17 -> 0 | M36: =(($D36*$G36)+$D36)+'การลงระหว่างเดือน ปี 2026'!AS17 -> 0 | N36: =(($D36*$G36)+$D36)+'การลงระหว่างเดือน ปี 2026'!AT17 -> 0 | O36: =(($D36*$G36)+$D36)+'การลงระหว่างเดือน ปี 2026'!AU17 -> 0 | P36: =(($D36*$G36)+$D36)+'การลงระหว่างเดือน ปี 2026'!AV17 -> 0 | ... T36: =(($D36*$G36)+$D36)+'การลงระหว่างเดือน ปี 2026'!AZ17 -> 0 | U36: =SUM(I36:T36) -> 0 | V36: =I36/$I$18 -> #DIV/0! | W36: =J36/$J$18 -> #DIV/0! | X36: =K36/$K$18 -> #DIV/0! | Y36: =L36/$L$18 -> #DIV/0! | Z36: =M36/$M$18 -> #DIV/0! | AA36: =N36/$N$18 -> #DIV/0! | AB36: =O36/$O$18 -> #DIV/0! | AC36: =P36/$P$18 -> #DIV/0! | AD36: =Q36/$Q$18 -> #DIV/0! | AE36: =R36/$R$18 -> #DIV/0! | AF36: =S36/$S$18 -> #DIV/0! | AG36: =T36/$T$18 -> #DIV/0! | AH36: =U36/$U$18 -> #DIV/0! | AI36: S | AJ36: =IFERROR(U36/E36,0)-1 -> -1
A37: ='งบกำไรขาดทุน ปี 2025'!A37 -> 61300010 | B37: ='งบกำไรขาดทุน ปี 2025'!B37 -> ค่าเสื่อมราคา - เครื่องมือแพทย์ | C37: ='งบกำไรขาดทุน ปี 2025'!O37 -> 0 | D37: =C37/$C$5 -> 0 | E37: =D37*$E$5 -> 0 | F37: =E37/$E$18 -> #DIV/0! | H37: x | I37: =(($D37*$G37)+$D37)+'การลงระหว่างเดือน ปี 2026'!AO18 -> 0 | J37: =(($D37*$G37)+$D37)+'การลงระหว่างเดือน ปี 2026'!AP18 -> 0 | K37: =(($D37*$G37)+$D37)+'การลงระหว่างเดือน ปี 2026'!AQ18 -> 0 | L37: =(($D37*$G37)+$D37)+'การลงระหว่างเดือน ปี 2026'!AR18 -> 0 | M37: =(($D37*$G37)+$D37)+'การลงระหว่างเดือน ปี 2026'!AS18 -> 0 | N37: =(($D37*$G37)+$D37)+'การลงระหว่างเดือน ปี 2026'!AT18 -> 0 | O37: =(($D37*$G37)+$D37)+'การลงระหว่างเดือน ปี 2026'!AU18 -> 0 | P37: =(($D37*$G37)+$D37)+'การลงระหว่างเดือน ปี 2026'!AV18 -> 0 | ... T37: =(($D37*$G37)+$D37)+'การลงระหว่างเดือน ปี 2026'!AZ18 -> 0 | U37: =SUM(I37:T37) -> 0 | V37: =I37/$I$18 -> #DIV/0! | W37: =J37/$J$18 -> #DIV/0! | X37: =K37/$K$18 -> #DIV/0! | Y37: =L37/$L$18 -> #DIV/0! | Z37: =M37/$M$18 -> #DIV/0! | AA37: =N37/$N$18 -> #DIV/0! | AB37: =O37/$O$18 -> #DIV/0! | AC37: =P37/$P$18 -> #DIV/0! | AD37: =Q37/$Q$18 -> #DIV/0! | AE37: =R37/$R$18 -> #DIV/0! | AF37: =S37/$S$18 -> #DIV/0! | AG37: =T37/$T$18 -> #DIV/0! | AH37: =U37/$U$18 -> #DIV/0! | AI37: F | AJ37: =IFERROR(U37/E37,0)-1 -> -1
A38: ='งบกำไรขาดทุน ปี 2025'!A38 -> 0 | B38: ='งบกำไรขาดทุน ปี 2025'!B38 -> รวมค่าใช้จ่ายในการขาย | C38: ='งบกำไรขาดทุน ปี 2025'!O38 -> 0 | D38: =C38/$C$5 -> 0 | E38: =D38*$E$5 -> 0 | F38: =E38/$E$18 -> #DIV/0! | I38: =SUM(I26:I37) -> #DIV/0! | J38: =SUM(J26:J37) -> #DIV/0! | K38: =SUM(K26:K37) -> #DIV/0! | L38: =SUM(L26:L37) -> #DIV/0! | M38: =SUM(M26:M37) -> #DIV/0! | N38: =SUM(N26:N37) -> #DIV/0! | O38: =SUM(O26:O37) -> #DIV/0! | P38: =SUM(P26:P37) -> #DIV/0! | ... T38: =SUM(T26:T37) -> #DIV/0! | U38: =SUM(U25:U37) -> #DIV/0! | V38: =I38/$I$18 -> #DIV/0! | W38: =J38/$J$18 -> #DIV/0! | X38: =K38/$K$18 -> #DIV/0! | Y38: =L38/$L$18 -> #DIV/0! | Z38: =M38/$M$18 -> #DIV/0! | AA38: =N38/$N$18 -> #DIV/0! | AB38: =O38/$O$18 -> #DIV/0! | AC38: =P38/$P$18 -> #DIV/0! | AD38: =Q38/$Q$18 -> #DIV/0! | AE38: =R38/$R$18 -> #DIV/0! | AF38: =S38/$S$18 -> #DIV/0! | AG38: =T38/$T$18 -> #DIV/0! | AH38: =U38/$U$18 -> #DIV/0! | AJ38: =IFERROR(U38/E38,0)-1 -> -1
A39: ='งบกำไรขาดทุน ปี 2025'!A39 -> 0 | B39: ='งบกำไรขาดทุน ปี 2025'!B39 -> ค่ายานพาหนะ | C39: ='งบกำไรขาดทุน ปี 2025'!O39 -> 0 | AJ39: =IFERROR(U39/E39,0)-1 -> -1
A40: ='งบกำไรขาดทุน ปี 2025'!A40 -> 52000015 | B40: ='งบกำไรขาดทุน ปี 2025'!B40 -> ค่าขนส่งในประเทศ | C40: ='งบกำไรขาดทุน ปี 2025'!O40 -> 0 | D40: =C40/$C$5 -> 0 | E40: =D40*$E$5 -> 0 | F40: =E40/$E$18 -> #DIV/0! | H40: V | I40: =((I$18*($F40+$G40))) -> #DIV/0! | J40: =((J$18*($F40+$G40))) -> #DIV/0! | K40: =((K$18*($F40+$G40))) -> #DIV/0! | L40: =((L$18*($F40+$G40))) -> #DIV/0! | M40: =((M$18*($F40+$G40))) -> #DIV/0! | N40: =((N$18*($F40+$G40))) -> #DIV/0! | O40: =((O$18*($F40+$G40))) -> #DIV/0! | P40: =((P$18*($F40+$G40))) -> #DIV/0! | ... T40: =((T$18*($F40+$G40))) -> #DIV/0! | U40: =SUM(I40:T40) -> #DIV/0! | V40: =I40/$I$18 -> #DIV/0! | W40: =J40/$J$18 -> #DIV/0! | X40: =K40/$K$18 -> #DIV/0! | Y40: =L40/$L$18 -> #DIV/0! | Z40: =M40/$M$18 -> #DIV/0! | AA40: =N40/$N$18 -> #DIV/0! | AB40: =O40/$O$18 -> #DIV/0! | AC40: =P40/$P$18 -> #DIV/0! | AD40: =Q40/$Q$18 -> #DIV/0! | AE40: =R40/$R$18 -> #DIV/0! | AF40: =S40/$S$18 -> #DIV/0! | AG40: =T40/$T$18 -> #DIV/0! | AH40: =U40/$U$18 -> #DIV/0! | AI40: V | AJ40: =IFERROR(U40/E40,0)-1 -> -1
...

Sheet การลงระหว่างเดือน ปี 2026
A1: THONGLOR PET HOSPITAL COMPANY LIMITED
A2: บริษัท โรงพยาบาลสัตว์ทองหล่อ จำกัด | G2: 0.01
B4: อายุการใช้งาน | C4: January | F4: February | I4: March | L4: April | O4: May | R4: June | U4: July | X4: August | AA4: September | AD4: October | AG4: November | AJ4: December | AM4: รวม | AO4: ลงระหว่างเดือนใน Budget
C5: รายละเอียด | D5: งบประมาณที่ใช้ | E5: ลงระหว่างเดือน | F5: รายละเอียด | G5: งบประมาณที่ใช้ | H5: ลงระหว่างเดือน | I5: รายละเอียด | J5: งบประมาณที่ใช้ | K5: ลงระหว่างเดือน | L5: รายละเอียด | M5: งบประมาณที่ใช้ | N5: ลงระหว่างเดือน | O5: รายละเอียด | P5: งบประมาณที่ใช้ | Q5: ลงระหว่างเดือน | R5: รายละเอียด | S5: งบประมาณที่ใช้ | T5: ลงระหว่างเดือน | U5: รายละเอียด | V5: งบประมาณที่ใช้ | W5: ลงระหว่างเดือน | X5: รายละเอียด | Y5: งบประมาณที่ใช้ | Z5: ลงระหว่างเดือน | AA5: รายละเอียด | AB5: งบประมาณที่ใช้ | AC5: ลงระหว่างเดือน | AD5: รายละเอียด | AE5: งบประมาณที่ใช้ | AF5: ลงระหว่างเดือน | AG5: รายละเอียด | AH5: งบประมาณที่ใช้ | AI5: ลงระหว่างเดือน | AJ5: รายละเอียด | AK5: งบประมาณที่ใช้ | AL5: ลงระหว่างเดือน | AO5: January | AP5: February | AQ5: March | AR5: April | AS5: May | AT5: June | AU5: July | AV5: August | AW5: September | AX5: October | AY5: November | AZ5: December
A6: รายได้ | BB6: รายได้ | BC6: JAN | BD6: FEB | BE6: MAR | BF6: APR | BG6: MAY | BH6: JUN | BI6: JUL | BJ6: AUG | BK6: SEP | BL6: OCT | BM6: NOV | BN6: DEC | BO6: Total | BP6: ผลต่าง
A7: รายได้จากการขาย - OPD/IPD | D7: =BC7 -> 0 | E7: =D7 -> 0 | G7: =BD7 -> 0 | H7: =G7 -> 0 | J7: =BE7 -> 0 | K7: =J7 -> 0 | M7: =BF7 -> 0 | N7: =M7 -> 0 | P7: =BG7 -> 0 | Q7: =P7 -> 0 | S7: =BH7 -> 0 | T7: =S7 -> 0 | V7: =BI7 -> 0 | W7: =V7 -> 0 | Y7: =BJ7 -> 0 | Z7: =Y7 -> 0 | AB7: =BK7 -> 0 | AC7: =AB7 -> 0 | AE7: =BL7 -> 0 | AF7: =AE7 -> 0 | AH7: =BM7 -> 0 | AI7: =AH7 -> 0 | AK7: =BN7 -> 0 | AL7: =AK7 -> 0 | AM7: =SUM(D7,G7,J7,M7,P7,S7,V7,Y7,AB7,AE7,AH7,AK7) -> 0 | AO7: =E7 -> 0 | AP7: =H7 -> 0 | AQ7: =K7 -> 0 | AR7: =N7 -> 0 | AS7: =Q7 -> 0 | AT7: =T7 -> 0 | AU7: =W7 -> 0 | AV7: =Z7 -> 0 | AW7: =AC7 -> 0 | AX7: =AF7 -> 0 | AY7: =AI7 -> 0 | AZ7: =AL7 -> 0 | BB7: รายได้จากการขาย - OPD/IPD | BO7: =SUM(BC7:BN7) -> 0 | BP7: =BO7-AM7 -> 0
A8: รายได้จากการขาย - Grooming | D8: =BC8 -> 0 | E8: =D8 -> 0 | G8: =BD8 -> 0 | H8: =G8 -> 0 | J8: =BE8 -> 0 | K8: =J8 -> 0 | M8: =BF8 -> 0 | N8: =M8 -> 0 | P8: =BG8 -> 0 | Q8: =P8 -> 0 | S8: =BH8 -> 0 | T8: =S8 -> 0 | V8: =BI8 -> 0 | W8: =V8 -> 0 | Y8: =BJ8 -> 0 | Z8: =Y8 -> 0 | AB8: =BK8 -> 0 | AC8: =AB8 -> 0 | AE8: =BL8 -> 0 | AF8: =AE8 -> 0 | AH8: =BM8 -> 0 | AI8: =AH8 -> 0 | AK8: =BN8 -> 0 | AL8: =AK8 -> 0 | AM8: =SUM(D8,G8,J8,M8,P8,S8,V8,Y8,AB8,AE8,AH8,AK8) -> 0 | AO8: =E8 -> 0 | AP8: =H8 -> 0 | AQ8: =K8 -> 0 | AR8: =N8 -> 0 | AS8: =Q8 -> 0 | AT8: =T8 -> 0 | AU8: =W8 -> 0 | AV8: =Z8 -> 0 | AW8: =AC8 -> 0 | AX8: =AF8 -> 0 | AY8: =AI8 -> 0 | AZ8: =AL8 -> 0 | BB8: รายได้จากการขาย - Grooming | BO8: =SUM(BC8:BN8) -> 0 | BP8: =BO8-AM8 -> 0
A9: รายได้จากการขาย - Petshop | D9: =BC9 -> 0 | E9: =D9 -> 0 | G9: =BD9 -> 0 | H9: =G9 -> 0 | J9: =BE9 -> 0 | K9: =J9 -> 0 | M9: =BF9 -> 0 | N9: =M9 -> 0 | P9: =BG9 -> 0 | Q9: =P9 -> 0 | S9: =BH9 -> 0 | T9: =S9 -> 0 | V9: =BI9 -> 0 | W9: =V9 -> 0 | Y9: =BJ9 -> 0 | Z9: =Y9 -> 0 | AB9: =BK9 -> 0 | AC9: =AB9 -> 0 | AE9: =BL9 -> 0 | AF9: =AE9 -> 0 | AH9: =BM9 -> 0 | AI9: =AH9 -> 0 | AK9: =BN9 -> 0 | AL9: =AK9 -> 0 | AM9: =SUM(D9,G9,J9,M9,P9,S9,V9,Y9,AB9,AE9,AH9,AK9) -> 0 | AO9: =E9 -> 0 | AP9: =H9 -> 0 | AQ9: =K9 -> 0 | AR9: =N9 -> 0 | AS9: =Q9 -> 0 | AT9: =T9 -> 0 | AU9: =W9 -> 0 | AV9: =Z9 -> 0 | AW9: =AC9 -> 0 | AX9: =AF9 -> 0 | AY9: =AI9 -> 0 | AZ9: =AL9 -> 0 | BB9: รายได้จากการขาย - Petshop | BO9: =SUM(BC9:BN9) -> 0 | BP9: =BO9-AM9 -> 0
A10: รายได้จากการขาย - Swimming | D10: =BC10 -> 0 | E10: =D10 -> 0 | G10: =BD10 -> 0 | H10: =G10 -> 0 | J10: =BE10 -> 0 | K10: =J10 -> 0 | M10: =BF10 -> 0 | N10: =M10 -> 0 | P10: =BG10 -> 0 | Q10: =P10 -> 0 | S10: =BH10 -> 0 | T10: =S10 -> 0 | V10: =BI10 -> 0 | W10: =V10 -> 0 | Y10: =BJ10 -> 0 | Z10: =Y10 -> 0 | AB10: =BK10 -> 0 | AC10: =AB10 -> 0 | AE10: =BL10 -> 0 | AF10: =AE10 -> 0 | AH10: =BM10 -> 0 | AI10: =AH10 -> 0 | AK10: =BN10 -> 0 | AL10: =AK10 -> 0 | AM10: =SUM(D10,G10,J10,M10,P10,S10,V10,Y10,AB10,AE10,AH10,AK10) -> 0 | AO10: =E10 -> 0 | AP10: =H10 -> 0 | AQ10: =K10 -> 0 | AR10: =N10 -> 0 | AS10: =Q10 -> 0 | AT10: =T10 -> 0 | AU10: =W10 -> 0 | AV10: =Z10 -> 0 | AW10: =AC10 -> 0 | AX10: =AF10 -> 0 | AY10: =AI10 -> 0 | AZ10: =AL10 -> 0 | BB10: รายได้จากการขาย - Swimming | BO10: =SUM(BC10:BN10) -> 0 | BP10: =BO10-AM10 -> 0
A11: รายได้จากการขาย - Pettaxi | D11: =BC11 -> 0 | E11: =D11 -> 0 | G11: =BD11 -> 0 | H11: =G11 -> 0 | J11: =BE11 -> 0 | K11: =J11 -> 0 | M11: =BF11 -> 0 | N11: =M11 -> 0 | P11: =BG11 -> 0 | Q11: =P11 -> 0 | S11: =BH11 -> 0 | T11: =S11 -> 0 | V11: =BI11 -> 0 | W11: =V11 -> 0 | Y11: =BJ11 -> 0 | Z11: =Y11 -> 0 | AB11: =BK11 -> 0 | AC11: =AB11 -> 0 | AE11: =BL11 -> 0 | AF11: =AE11 -> 0 | AH11: =BM11 -> 0 | AI11: =AH11 -> 0 | AK11: =BN11 -> 0 | AL11: =AK11 -> 0 | AM11: =SUM(D11,G11,J11,M11,P11,S11,V11,Y11,AB11,AE11,AH11,AK11) -> 0 | AO11: =E11 -> 0 | AP11: =H11 -> 0 | AQ11: =K11 -> 0 | AR11: =N11 -> 0 | AS11: =Q11 -> 0 | AT11: =T11 -> 0 | AU11: =W11 -> 0 | AV11: =Z11 -> 0 | AW11: =AC11 -> 0 | AX11: =AF11 -> 0 | AY11: =AI11 -> 0 | AZ11: =AL11 -> 0 | BB11: รายได้จากการขาย - Pettaxi | BO11: =SUM(BC11:BN11) -> 0 | BP11: =BO11-AM11 -> 0
A12: ค่าใช้จ่ายในการขาย | BB12: Total | BC12: =SUM(BC7:BC11) -> 0 | BD12: =SUM(BD7:BD11) -> 0 | BE12: =SUM(BE7:BE11) -> 0 | BF12: =SUM(BF7:BF11) -> 0 | BG12: =SUM(BG7:BG11) -> 0 | BH12: =SUM(BH7:BH11) -> 0 | BI12: =SUM(BI7:BI11) -> 0 | BJ12: =SUM(BJ7:BJ11) -> 0 | ... BO12: =SUM(BO7:BO11) -> 0
A13: ค่าส่งเสริมการขาย | B13: โปร คูปอง หรือสิทธิ์ที่ให้ลูกค้าเพื่อเร่งยอดขาย | E13: =D13 -> 0 | H13: =G13 -> 0 | K13: =J13 -> 0 | N13: =M13 -> 0 | Q13: =P13 -> 0 | T13: =S13 -> 0 | W13: =V13 -> 0 | Z13: =Y13 -> 0 | AC13: =AB13 -> 0 | AF13: =AE13 -> 0 | AI13: =AH13 -> 0 | AL13: =AK13 -> 0 | AM13: =SUM(D13,G13,J13,M13,P13,S13,V13,Y13,AB13,AE13,AH13,AK13) -> 0 | AO13: =E13 -> 0 | AP13: =H13 -> 0 | AQ13: =K13 -> 0 | AR13: =N13 -> 0 | AS13: =Q13 -> 0 | AT13: =T13 -> 0 | AU13: =W13 -> 0 | AV13: =Z13 -> 0 | AW13: =AC13 -> 0 | AX13: =AF13 -> 0 | AY13: =AI13 -> 0 | AZ13: =AL13 -> 0
A14: ค่าบริการวิชาชีพแพทย์ | D14: ='กำลัง VET'!E30 -> 0 | E14: =D14 -> 0 | G14: ='กำลัง VET'!F30 -> 0 | H14: =E14+G14 -> 0 | J14: ='กำลัง VET'!G30 -> 0 | K14: =H14+J14 -> 0 | M14: ='กำลัง VET'!H30 -> 0 | N14: =K14+M14 -> 0 | P14: ='กำลัง VET'!I30 -> 0 | Q14: =N14+P14 -> 0 | S14: ='กำลัง VET'!J30 -> 0 | T14: =Q14+S14 -> 0 | V14: ='กำลัง VET'!K30 -> 0 | W14: =T14+V14 -> 0 | Y14: ='กำลัง VET'!L30 -> 0 | Z14: =W14+Y14 -> 0 | AB14: ='กำลัง VET'!M30 -> 0 | AC14: =Z14+AB14 -> 0 | AE14: ='กำลัง VET'!N30 -> 0 | AF14: =AC14+AE14 -> 0 | AH14: ='กำลัง VET'!O30 -> 0 | AI14: =AF14+AH14 -> 0 | AK14: ='กำลัง VET'!P30 -> 0 | AL14: =AI14+AK14 -> 0 | AM14: =SUM(D14,G14,J14,M14,P14,S14,V14,Y14,AB14,AE14,AH14,AK14) -> 0 | AO14: =E14 -> 0 | AP14: =H14 -> 0 | AQ14: =K14 -> 0 | AR14: =N14 -> 0 | AS14: =Q14 -> 0 | AT14: =T14 -> 0 | AU14: =W14 -> 0 | AV14: =Z14 -> 0 | AW14: =AC14 -> 0 | AX14: =AF14 -> 0 | AY14: =AI14 -> 0 | AZ14: =AL14 -> 0
A15: ค่าเช่าเครื่องมือแพทย์ | E15: =D15 -> 0 | H15: =G15 -> 0 | K15: =J15 -> 0 | N15: =M15 -> 0 | Q15: =P15 -> 0 | T15: =S15 -> 0 | W15: =V15 -> 0 | Z15: =Y15 -> 0 | AC15: =AB15 -> 0 | AF15: =AE15 -> 0 | AI15: =AH15 -> 0 | AL15: =AK15 -> 0 | AM15: =SUM(D15,G15,J15,M15,P15,S15,V15,Y15,AB15,AE15,AH15,AK15) -> 0 | AO15: =E15 -> 0 | AP15: =H15 -> 0 | AQ15: =K15 -> 0 | AR15: =N15 -> 0 | AS15: =Q15 -> 0 | AT15: =T15 -> 0 | AU15: =W15 -> 0 | AV15: =Z15 -> 0 | AW15: =AC15 -> 0 | AX15: =AF15 -> 0 | AY15: =AI15 -> 0 | AZ15: =AL15 -> 0
A16: ค่าวัสดุเครื่องมือแพทย์ | E16: =D16 -> 0 | H16: =G16 -> 0 | K16: =J16 -> 0 | N16: =M16 -> 0 | Q16: =P16 -> 0 | T16: =S16 -> 0 | W16: =V16 -> 0 | Z16: =Y16 -> 0 | AC16: =AB16 -> 0 | AF16: =AE16 -> 0 | AI16: =AH16 -> 0 | AL16: =AK16 -> 0 | AM16: =SUM(D16,G16,J16,M16,P16,S16,V16,Y16,AB16,AE16,AH16,AK16) -> 0 | AO16: =E16 -> 0 | AP16: =H16 -> 0 | AQ16: =K16 -> 0 | AR16: =N16 -> 0 | AS16: =Q16 -> 0 | AT16: =T16 -> 0 | AU16: =W16 -> 0 | AV16: =Z16 -> 0 | AW16: =AC16 -> 0 | AX16: =AF16 -> 0 | AY16: =AI16 -> 0 | AZ16: =AL16 -> 0
A17: ค่าเช่าอุปกรณ์-เครื่องมือระหว่างสาขา | E17: =D17 -> 0 | H17: =G17 -> 0 | K17: =J17 -> 0 | N17: =M17 -> 0 | Q17: =P17 -> 0 | T17: =S17 -> 0 | W17: =V17 -> 0 | Z17: =Y17 -> 0 | AC17: =AB17 -> 0 | AF17: =AE17 -> 0 | AI17: =AH17 -> 0 | AL17: =AK17 -> 0 | AM17: =SUM(D17,G17,J17,M17,P17,S17,V17,Y17,AB17,AE17,AH17,AK17) -> 0 | AO17: =E17 -> 0 | AP17: =H17 -> 0 | AQ17: =K17 -> 0 | AR17: =N17 -> 0 | AS17: =Q17 -> 0 | AT17: =T17 -> 0 | AU17: =W17 -> 0 | AV17: =Z17 -> 0 | AW17: =AC17 -> 0 | AX17: =AF17 -> 0 | AY17: =AI17 -> 0 | AZ17: =AL17 -> 0
A18: ค่าเสื่อมราคา - เครื่องมือแพทย์ | B18: 0.2 | D18: =เครื่องมือแพทย์!E61 -> 0 | E18: =((D18*$B$18)/12) -> 0 | G18: =เครื่องมือแพทย์!F61 -> 0 | H18: =((G18*$B$18)/12)+E18 -> 0 | J18: =เครื่องมือแพทย์!G61 -> 0 | K18: =((J18*$B$18)/12)+H18 -> 0 | M18: =เครื่องมือแพทย์!H61 -> 0 | N18: =((M18*$B$18)/12)+K18 -> 0 | P18: =เครื่องมือแพทย์!I61 -> 0 | Q18: =((P18*$B$18)/12)+N18 -> 0 | S18: =เครื่องมือแพทย์!J61 -> 0 | T18: =((S18*$B$18)/12)+Q18 -> 0 | V18: =เครื่องมือแพทย์!K61 -> 0 | W18: =((V18*$B$18)/12)+T18 -> 0 | Y18: =เครื่องมือแพทย์!L61 -> 0 | Z18: =((Y18*$B$18)/12)+W18 -> 0 | AB18: =เครื่องมือแพทย์!M61 -> 0 | AC18: =((AB18*$B$18)/12)+Z18 -> 0 | AE18: =เครื่องมือแพทย์!N61 -> 0 | AF18: =((AE18*$B$18)/12)+AC18 -> 0 | AH18: =เครื่องมือแพทย์!O61 -> 0 | AI18: =((AH18*$B$18)/12)+AF18 -> 0 | AK18: =เครื่องมือแพทย์!P61 -> 0 | AL18: =((AK18*$B$18)/12)+AI18 -> 0 | AM18: =SUM(D18,G18,J18,M18,P18,S18,V18,Y18,AB18,AE18,AH18,AK18) -> 0 | AO18: =E18 -> 0 | AP18: =H18 -> 0 | AQ18: =K18 -> 0 | AR18: =N18 -> 0 | AS18: =Q18 -> 0 | AT18: =T18 -> 0 | AU18: =W18 -> 0 | AV18: =Z18 -> 0 | AW18: =AC18 -> 0 | AX18: =AF18 -> 0 | AY18: =AI18 -> 0 | AZ18: =AL18 -> 0
A19: เงินเดือนและสวัสดิการพนักงาน
A20: เงินเดือน | D20: ='กำลังคนNON VET'!F50+ปรับตำแหน่ง!E29 -> 0 | E20: =D20 -> 0 | G20: ='กำลังคนNON VET'!G50+ปรับตำแหน่ง!F29 -> 0 | H20: =G20+E20 -> 0 | J20: ='กำลังคนNON VET'!H50+ปรับตำแหน่ง!G29 -> 0 | K20: =J20+H20 -> 0 | M20: ='กำลังคนNON VET'!I50+ปรับตำแหน่ง!H29 -> 0 | N20: =M20+K20 -> 0 | P20: ='กำลังคนNON VET'!J50+ปรับตำแหน่ง!I29 -> 0 | Q20: =P20+N20 -> 0 | S20: ='กำลังคนNON VET'!K50+ปรับตำแหน่ง!J29 -> 0 | T20: =S20+Q20 -> 0 | V20: ='กำลังคนNON VET'!L50+ปรับตำแหน่ง!K29 -> 0 | W20: =V20+T20 -> 0 | Y20: ='กำลังคนNON VET'!M50+ปรับตำแหน่ง!L29 -> 0 | Z20: =Y20+W20 -> 0 | AB20: ='กำลังคนNON VET'!N50+ปรับตำแหน่ง!M29 -> 0 | AC20: =AB20+Z20 -> 0 | AE20: ='กำลังคนNON VET'!O50+ปรับตำแหน่ง!N29 -> 0 | AF20: =AE20+AC20 -> 0 | AH20: ='กำลังคนNON VET'!P50+ปรับตำแหน่ง!O29 -> 0 | AI20: =AH20+AF20 -> 0 | AK20: ='กำลังคนNON VET'!Q50+ปรับตำแหน่ง!P29 -> 0 | AL20: =AK20+AI20 -> 0 | AM20: =SUM(D20,G20,J20,M20,P20,S20,V20,Y20,AB20,AE20,AH20,AK20) -> 0 | AO20: =E20 -> 0 | AP20: =H20 -> 0 | AQ20: =K20 -> 0 | AR20: =N20 -> 0 | AS20: =Q20 -> 0 | AT20: =T20 -> 0 | AU20: =W20 -> 0 | AV20: =Z20 -> 0 | AW20: =AC20 -> 0 | AX20: =AF20 -> 0 | AY20: =AI20 -> 0 | AZ20: =AL20 -> 0
A21: ค่าหัวหน้าฝ่ายวิชาการแพทย์ | E21: =D21 -> 0 | H21: =G21+E21 -> 0 | K21: =J21+H21 -> 0 | N21: =M21+K21 -> 0 | Q21: =P21+N21 -> 0 | T21: =S21+Q21 -> 0 | W21: =V21+T21 -> 0 | Z21: =Y21+W21 -> 0 | AC21: =AB21+Z21 -> 0 | AF21: =AE21+AC21 -> 0 | AI21: =AH21+AF21 -> 0 | AL21: =AK21+AI21 -> 0 | AM21: =SUM(D21,G21,J21,M21,P21,S21,V21,Y21,AB21,AE21,AH21,AK21) -> 0 | AO21: =E21 -> 0 | AP21: =H21 -> 0 | AQ21: =K21 -> 0 | AR21: =N21 -> 0 | AS21: =Q21 -> 0 | AT21: =T21 -> 0 | AU21: =W21 -> 0 | AV21: =Z21 -> 0 | AW21: =AC21 -> 0 | AX21: =AF21 -> 0 | AY21: =AI21 -> 0 | AZ21: =AL21 -> 0
A22: เงินเดือนพยาบาล (ไม่ใช้อันนี้) | AO22: =E22 -> 0 | AP22: =H22 -> 0 | AQ22: =K22 -> 0 | AR22: =N22 -> 0 | AS22: =Q22 -> 0 | AT22: =T22 -> 0 | AU22: =W22 -> 0 | AV22: =Z22 -> 0 | AW22: =AC22 -> 0 | AX22: =AF22 -> 0 | AY22: =AI22 -> 0 | AZ22: =AL22 -> 0
A23: ค่าเช่ายานพาหนะ | E23: =D23 -> 0 | H23: =G23+E23 -> 0 | K23: =J23+H23 -> 0 | N23: =M23+K23 -> 0 | Q23: =P23+N23 -> 0 | T23: =S23+Q23 -> 0 | W23: =V23+T23 -> 0 | Z23: =Y23+W23 -> 0 | AC23: =AB23+Z23 -> 0 | AF23: =AE23+AC23 -> 0 | AI23: =AH23+AF23 -> 0 | AL23: =AK23+AI23 -> 0 | AM23: =SUM(D23,G23,J23,M23,P23,S23,V23,Y23,AB23,AE23,AH23,AK23) -> 0 | AO23: =E23 -> 0 | AP23: =H23 -> 0 | AQ23: =K23 -> 0 | AR23: =N23 -> 0 | AS23: =Q23 -> 0 | AT23: =T23 -> 0 | AU23: =W23 -> 0 | AV23: =Z23 -> 0 | AW23: =AC23 -> 0 | AX23: =AF23 -> 0 | AY23: =AI23 -> 0 | AZ23: =AL23 -> 0
A24: ค่าวัดระดับ/ค่าตำแหน่ง | D24: ='กำลังคนNON VET'!F75+ปรับตำแหน่ง!E44 -> 0 | E24: =D24 -> 0 | G24: ='กำลังคนNON VET'!G75+ปรับตำแหน่ง!F44 -> 0 | H24: =G24+E24 -> 0 | J24: ='กำลังคนNON VET'!H75+ปรับตำแหน่ง!G44 -> 0 | K24: =J24+H24 -> 0 | M24: ='กำลังคนNON VET'!I75+ปรับตำแหน่ง!H44 -> 0 | N24: =M24+K24 -> 0 | P24: ='กำลังคนNON VET'!J75+ปรับตำแหน่ง!I44 -> 0 | Q24: =P24+N24 -> 0 | S24: ='กำลังคนNON VET'!K75+ปรับตำแหน่ง!J44 -> 0 | T24: =S24+Q24 -> 0 | V24: ='กำลังคนNON VET'!L75+ปรับตำแหน่ง!K44 -> 0 | W24: =V24+T24 -> 0 | Y24: ='กำลังคนNON VET'!M75+ปรับตำแหน่ง!L44 -> 0 | Z24: =Y24+W24 -> 0 | AB24: ='กำลังคนNON VET'!N75+ปรับตำแหน่ง!M44 -> 0 | AC24: =AB24+Z24 -> 0 | AE24: ='กำลังคนNON VET'!O75+ปรับตำแหน่ง!N44 -> 0 | AF24: =AE24+AC24 -> 0 | AH24: ='กำลังคนNON VET'!P75+ปรับตำแหน่ง!O44 -> 0 | AI24: =AH24+AF24 -> 0 | AK24: ='กำลังคนNON VET'!Q75+ปรับตำแหน่ง!P44 -> 0 | AL24: =AK24+AI24 -> 0 | AM24: =SUM(D24,G24,J24,M24,P24,S24,V24,Y24,AB24,AE24,AH24,AK24) -> 0 | AO24: =E24 -> 0 | AP24: =H24 -> 0 | AQ24: =K24 -> 0 | AR24: =N24 -> 0 | AS24: =Q24 -> 0 | AT24: =T24 -> 0 | AU24: =W24 -> 0 | AV24: =Z24 -> 0 | AW24: =AC24 -> 0 | AX24: =AF24 -> 0 | AY24: =AI24 -> 0 | AZ24: =AL24 -> 0
A25: เงินกองทุนสำรองเลี้ยงชีพ | B25: 0.02 | D25: =(D20+D21+D22)*$B$25 -> 0 | E25: =D25 -> 0 | G25: =(G20+G21+G22)*$B$25 -> 0 | H25: =G25+E25 -> 0 | J25: =(J20+J21+J22)*$B$25 -> 0 | K25: =J25+H25 -> 0 | M25: =(M20+M21+M22)*$B$25 -> 0 | N25: =M25+K25 -> 0 | P25: =(P20+P21+P22)*$B$25 -> 0 | Q25: =P25+N25 -> 0 | S25: =(S20+S21+S22)*$B$25 -> 0 | T25: =S25+Q25 -> 0 | V25: =(V20+V21+V22)*$B$25 -> 0 | W25: =V25+T25 -> 0 | Y25: =(Y20+Y21+Y22)*$B$25 -> 0 | Z25: =Y25+W25 -> 0 | AB25: =(AB20+AB21+AB22)*$B$25 -> 0 | AC25: =AB25+Z25 -> 0 | AE25: =(AE20+AE21+AE22)*$B$25 -> 0 | AF25: =AE25+AC25 -> 0 | AH25: =(AH20+AH21+AH22)*$B$25 -> 0 | AI25: =AH25+AF25 -> 0 | AK25: =(AK20+AK21+AK22)*$B$25 -> 0 | AL25: =AK25+AI25 -> 0 | AM25: =SUM(D25,G25,J25,M25,P25,S25,V25,Y25,AB25,AE25,AH25,AK25) -> 0 | AO25: =E25 -> 0 | AP25: =H25 -> 0 | AQ25: =K25 -> 0 | AR25: =N25 -> 0 | AS25: =Q25 -> 0 | AT25: =T25 -> 0 | AU25: =W25 -> 0 | AV25: =Z25 -> 0 | AW25: =AC25 -> 0 | AX25: =AF25 -> 0 | AY25: =AI25 -> 0 | AZ25: =AL25 -> 0
A26: ค่าสวัสดิการพนักงาน | B26: 0.15 | D26: =(D20+D21+D22)*$B$26 -> 0 | E26: =D26 -> 0 | G26: =(G20+G21+G22)*$B$26 -> 0 | H26: =G26+E26 -> 0 | J26: =(J20+J21+J22)*$B$26 -> 0 | K26: =J26+H26 -> 0 | M26: =(M20+M21+M22)*$B$26 -> 0 | N26: =M26+K26 -> 0 | P26: =(P20+P21+P22)*$B$26 -> 0 | Q26: =P26+N26 -> 0 | S26: =(S20+S21+S22)*$B$26 -> 0 | T26: =S26+Q26 -> 0 | V26: =(V20+V21+V22)*$B$26 -> 0 | W26: =V26+T26 -> 0 | Y26: =(Y20+Y21+Y22)*$B$26 -> 0 | Z26: =Y26+W26 -> 0 | AB26: =(AB20+AB21+AB22)*$B$26 -> 0 | AC26: =AB26+Z26 -> 0 | AE26: =(AE20+AE21+AE22)*$B$26 -> 0 | AF26: =AE26+AC26 -> 0 | AH26: =(AH20+AH21+AH22)*$B$26 -> 0 | AI26: =AH26+AF26 -> 0 | AK26: =(AK20+AK21+AK22)*$B$26 -> 0 | AL26: =AK26+AI26 -> 0 | AM26: =SUM(D26,G26,J26,M26,P26,S26,V26,Y26,AB26,AE26,AH26,AK26) -> 0 | AO26: =E26 -> 0 | AP26: =H26 -> 0 | AQ26: =K26 -> 0 | AR26: =N26 -> 0 | AS26: =Q26 -> 0 | AT26: =T26 -> 0 | AU26: =W26 -> 0 | AV26: =Z26 -> 0 | AW26: =AC26 -> 0 | AX26: =AF26 -> 0 | AY26: =AI26 -> 0 | AZ26: =AL26 -> 0
